Workbook

Sheet Overview
A1: Category | B1: Details
A2: Document Name | B2: EMI Task-Level Coverage testcases
A3: Epic / Story Ref | B3: Jira Tasks above EMI-5794 with no prior coverage
A4: Release Number | B4: Mixed - see per-sheet ticket references
A5: Environment | B5: UAT
A6: Testing Period | B6: Sprint Test Execution Cycle
A9: EMI Task-Level Coverage — Test Case Results by Feature Cluster
A11: Category (Feature Cluster / Tickets) | B11: Passed | C11: Failed | D11: Partially Passed | E11: Not Tested | F11: Not Implemented | G11: Total Checks | H11: Pass Rate %
A12: EMI-5842 / 5843 / 5844 / 5845 - Contact Name & Number per Delivery Group | B12: =COUNTIF('POS Order Contact Details'!H2:H400, "Passed") | C12: =COUNTIF('POS Order Contact Details'!H2:H400, "Failed") | D12: =COUNTIF('POS Order Contact Details'!H2:H400, "Partially Passed") | E12: =COUNTIF('POS Order Contact Details'!H2:H400, "Not Tested") | F12: =COUNTIF('POS Order Contact Details'!H2:H400, "Not Implemented") | G12: =SUM(B12:F12) | H12: =IF(G12>0, B12/G12, 0)
A13: EMI-5846 / 5847 / 5848 / 5849 / 5850 - Delivery Consent Attachment | B13: =COUNTIF('POS Delivery Consent'!H2:H400, "Passed") | C13: =COUNTIF('POS Delivery Consent'!H2:H400, "Failed") | D13: =COUNTIF('POS Delivery Consent'!H2:H400, "Partially Passed") | E13: =COUNTIF('POS Delivery Consent'!H2:H400, "Not Tested") | F13: =COUNTIF('POS Delivery Consent'!H2:H400, "Not Implemented") | G13: =SUM(B13:F13) | H13: =IF(G13>0, B13/G13, 0)
A14: EMI-5853 / 5854 / 5855 / 5856 / 5857 - Device Management Implementation | B14: =COUNTIF('Device Management Impl'!H2:H400, "Passed") | C14: =COUNTIF('Device Management Impl'!H2:H400, "Failed") | D14: =COUNTIF('Device Management Impl'!H2:H400, "Partially Passed") | E14: =COUNTIF('Device Management Impl'!H2:H400, "Not Tested") | F14: =COUNTIF('Device Management Impl'!H2:H400, "Not Implemented") | G14: =SUM(B14:F14) | H14: =IF(G14>0, B14/G14, 0)
A15: EMI-5834 / 5952 / 5953 / 5956 / 5957 - Roles, Groups & Privileges | B15: =COUNTIF('RBAC Roles & Groups'!H2:H400, "Passed") | C15: =COUNTIF('RBAC Roles & Groups'!H2:H400, "Failed") | D15: =COUNTIF('RBAC Roles & Groups'!H2:H400, "Partially Passed") | E15: =COUNTIF('RBAC Roles & Groups'!H2:H400, "Not Tested") | F15: =COUNTIF('RBAC Roles & Groups'!H2:H400, "Not Implemented") | G15: =SUM(B15:F15) | H15: =IF(G15>0, B15/G15, 0)
A16: EMI-6057 / 6058 / 6059 - Registration Session Refresh Token (FE) | B16: =COUNTIF('Registration Refresh Token'!H2:H400, "Passed") | C16: =COUNTIF('Registration Refresh Token'!H2:H400, "Failed") | D16: =COUNTIF('Registration Refresh Token'!H2:H400, "Partially Passed") | E16: =COUNTIF('Registration Refresh Token'!H2:H400, "Not Tested") | F16: =COUNTIF('Registration Refresh Token'!H2:H400, "Not Implemented") | G16: =SUM(B16:F16) | H16: =IF(G16>0, B16/G16, 0)
A17: EMI-6007 / 6009 / 6034 - ANB PTS Fetch, MT940 Matching & POS Lifecycle | B17: =COUNTIF('ANB Settlement Files'!H2:H400, "Passed") | C17: =COUNTIF('ANB Settlement Files'!H2:H400, "Failed") | D17: =COUNTIF('ANB Settlement Files'!H2:H400, "Partially Passed") | E17: =COUNTIF('ANB Settlement Files'!H2:H400, "Not Tested") | F17: =COUNTIF('ANB Settlement Files'!H2:H400, "Not Implemented") | G17: =SUM(B17:F17) | H17: =IF(G17>0, B17/G17, 0)
A18: EMI-6019 - PoS Gateway Third-Party Acquiring Partner Integration | B18: =COUNTIF('PoS Gateway Integration'!H2:H400, "Passed") | C18: =COUNTIF('PoS Gateway Integration'!H2:H400, "Failed") | D18: =COUNTIF('PoS Gateway Integration'!H2:H400, "Partially Passed") | E18: =COUNTIF('PoS Gateway Integration'!H2:H400, "Not Tested") | F18: =COUNTIF('PoS Gateway Integration'!H2:H400, "Not Implemented") | G18: =SUM(B18:F18) | H18: =IF(G18>0, B18/G18, 0)
A19: EMI-6013 / 6015 - Admin POS Device Transactions & ACH Records | B19: =COUNTIF('Admin POS Surfaces'!H2:H400, "Passed") | C19: =COUNTIF('Admin POS Surfaces'!H2:H400, "Failed") | D19: =COUNTIF('Admin POS Surfaces'!H2:H400, "Partially Passed") | E19: =COUNTIF('Admin POS Surfaces'!H2:H400, "Not Tested") | F19: =COUNTIF('Admin POS Surfaces'!H2:H400, "Not Implemented") | G19: =SUM(B19:F19) | H19: =IF(G19>0, B19/G19, 0)
A20: EMI-6020 / 5861 / 6036 / 5908 - Amount Calculation, Fee Deduction & Metadata | B20: =COUNTIF('Transaction Amounts & Fees'!H2:H400, "Passed") | C20: =COUNTIF('Transaction Amounts & Fees'!H2:H400, "Failed") | D20: =COUNTIF('Transaction Amounts & Fees'!H2:H400, "Partially Passed") | E20: =COUNTIF('Transaction Amounts & Fees'!H2:H400, "Not Tested") | F20: =COUNTIF('Transaction Amounts & Fees'!H2:H400, "Not Implemented") | G20: =SUM(B20:F20) | H20: =IF(G20>0, B20/G20, 0)
A21: EMI-6035 / 5958 - Pending Reason Persistence & Rebuild Fix | B21: =COUNTIF('Pending Reason & Rebuild Fix'!H2:H400, "Passed") | C21: =COUNTIF('Pending Reason & Rebuild Fix'!H2:H400, "Failed") | D21: =COUNTIF('Pending Reason & Rebuild Fix'!H2:H400, "Partially Passed") | E21: =COUNTIF('Pending Reason & Rebuild Fix'!H2:H400, "Not Tested") | F21: =COUNTIF('Pending Reason & Rebuild Fix'!H2:H400, "Not Implemented") | G21: =SUM(B21:F21) | H21: =IF(G21>0, B21/G21, 0)
A22: EMI-5913 / 5927 / 5859 - OTP Hashing, Lean Errors & Security Remediation | B22: =COUNTIF('Security & Logging'!H2:H400, "Passed") | C22: =COUNTIF('Security & Logging'!H2:H400, "Failed") | D22: =COUNTIF('Security & Logging'!H2:H400, "Partially Passed") | E22: =COUNTIF('Security & Logging'!H2:H400, "Not Tested") | F22: =COUNTIF('Security & Logging'!H2:H400, "Not Implemented") | G22: =SUM(B22:F22) | H22: =IF(G22>0, B22/G22, 0)
A23: EMI-5831 / 5833 / 5966 - Locale Handling, Message Coverage & Translations | B23: =COUNTIF('Localisation & Messages'!H2:H400, "Passed") | C23: =COUNTIF('Localisation & Messages'!H2:H400, "Failed") | D23: =COUNTIF('Localisation & Messages'!H2:H400, "Partially Passed") | E23: =COUNTIF('Localisation & Messages'!H2:H400, "Not Tested") | F23: =COUNTIF('Localisation & Messages'!H2:H400, "Not Implemented") | G23: =SUM(B23:F23) | H23: =IF(G23>0, B23/G23, 0)
A24: EMI-5961 / 5938 / 5962 / 5963 / 5851 / 5852 - Customer & Business App Updates | B24: =COUNTIF('Customer App Updates'!H2:H400, "Passed") | C24: =COUNTIF('Customer App Updates'!H2:H400, "Failed") | D24: =COUNTIF('Customer App Updates'!H2:H400, "Partially Passed") | E24: =COUNTIF('Customer App Updates'!H2:H400, "Not Tested") | F24: =COUNTIF('Customer App Updates'!H2:H400, "Not Implemented") | G24: =SUM(B24:F24) | H24: =IF(G24>0, B24/G24, 0)
A25: Total | B25: =SUM(B12:B24) | C25: =SUM(C12:C24) | D25: =SUM(D12:D24) | E25: =SUM(E12:E24) | F25: =SUM(F12:F24) | G25: =SUM(G12:G24) | H25: =IF(G25>0, B25/G25, 0)
A27: Test Execution Statuses & Definitions
A28: Status | B28: Definition / Criteria | C28: Allowed In Workflow
A29: Passed | B29: All test steps executed with actual result matching the expected result | C29: Yes
A30: Failed | B30: One or more test steps failed or produced an incorrect result | C30: Yes
A31: Partially Passed | B31: Core functionality works but a secondary assertion did not | C31: Yes
A32: Not Tested | B32: Test case is ready for execution in the current cycle | C32: Yes (Default)
A33: Not Implemented | B33: Feature or endpoint dependency is currently unavailable | C33: Yes
A34: NA | B34: Scenario is not applicable to the current scope or configuration | C34: Yes

Sheet POS Order Contact Details
A1: Subtopic / Category | B1: TC ID | C1: Title | D1: Priority | E1: Preconditions | F1: Steps | G1: Expected Result | H1: Status | I1: Test Type
A2: Functional | B2: TC-Contact-01 | C2: Business Enters Contact Name and Mobile per Delivery Group - Web | D2: High | E2: Business user signed in on Web; a POS request with more than one delivery group | F2: 1. Open the POS request flow 2. Enter a distinct contact name and mobile number on each delivery group 3. Submit | G2: Each group accepts its own contact pair independently; the values are sent in the POS request/order payload against the correct group | H2: Not Tested | I2: Functional
A3: Functional | B3: TC-Contact-02 | C3: Contact Values Reach the Backend Against the Right Group | D3: High | E3: A submitted multi-group POS order | F3: 1. Inspect the request payload and the stored order | G3: Each group's contact name and mobile are stored against that group; no value is carried across groups | H3: Not Tested | I3: Functional
A4: Functional | B4: TC-Contact-03 | C4: POS Order Details Display Contact Under the Right Group - Web Business | D4: Medium | E4: A submitted multi-group POS order | F4: 1. Open POS Order details as the business user | G4: Contact name and mobile appear under their respective delivery group | H4: Not Tested | I4: Functional
A5: Functional | B5: TC-Contact-04 | C5: Admin Sees Contact Name and Number on Order Details | D5: High | E5: A submitted multi-group POS order; admin signed in | F5: 1. Open the POS Order details in Admin | G5: Contact name and mobile are displayed per delivery group, matching what the business submitted | H5: Not Tested | I5: Functional
A6: Platform | B6: TC-Contact-05 | C6: Android Business Captures and Submits Contact per Group | D6: High | E6: Business user on the Android app | F6: 1. Repeat TC-Contact-01 on Android 2. Submit and inspect the payload | G6: Behaviour matches Web: per-group capture, correct payload, values visible on order details | H6: Not Tested | I6: Cross-Platform
A7: Platform | B7: TC-Contact-06 | C7: iOS Business Captures and Submits Contact per Group | D7: High | E7: Business user on the iOS app | F7: 1. Repeat TC-Contact-01 on iOS 2. Submit and inspect the payload | G7: Behaviour matches Web: per-group capture, correct payload, values visible on order details | H7: Not Tested | I7: Cross-Platform
A8: Platform | B8: TC-Contact-07 | C8: Contact Values Are Consistent Across All Three Clients | D8: Medium | E8: One order created on each of Web, Android and iOS | F8: 1. Create the same order shape on each client 2. Compare the stored payloads | G8: All three produce the same stored structure; no client sends a different field name, shape or nesting | H8: Not Tested | I8: Cross-Platform
A9: Validation | B9: TC-Contact-08 | C9: Backend Validation Errors Are Surfaced to the User | D9: High | E9: A backend rule that rejects a malformed contact number | F9: 1. Submit an invalid mobile number 2. Observe the client | G9: The backend validation error is displayed to the user rather than swallowed or replaced by a generic failure | H9: Not Tested | I9: Negative
A10: Validation | B10: TC-Contact-09 | C10: Invalid Mobile Number Format Is Rejected | D10: Medium | E10: POS request flow open | F10: 1. Enter a mobile number that is too short, too long and non-numeric in turn 2. Attempt to submit | G10: Each is rejected with a clear message and the order is not created | H10: Not Tested | I10: Negative
A11: Validation | B11: TC-Contact-10 | C11: Missing Contact on One Group of Several | D11: Medium | E11: A multi-group POS request | F11: 1. Complete contact details on one group and leave another empty 2. Submit | G11: The rule is applied consistently across every group and the message identifies which group is incomplete | H11: Not Tested | I11: Negative
A12: Validation | B12: TC-Contact-11 | C12: Contact Name Accepts Arabic and Latin Characters | D12: Medium | E12: POS request flow open | F12: 1. Enter an Arabic contact name, then a Latin one 2. Submit and re-open the order | G12: Both are accepted, stored and rendered without corruption on every surface | H12: Not Tested | I12: Negative
... A15: Regression | B15: TC-Contact-14 | C15: Existing Orders Without Contact Details Still Render | D15: Medium | E15: A POS order created before this change | F15: 1. Open its details on Admin and on each business client | G15: The order renders without error; absent contact fields are handled gracefully rather than showing blanks as errors | H15: Not Tested | I15: Integration

Sheet POS Delivery Consent
A1: Subtopic / Category | B1: TC ID | C1: Title | D1: Priority | E1: Preconditions | F1: Steps | G1: Expected Result | H1: Status | I1: Test Type
A2: Functional | B2: TC-Consent-01 | C2: Admin Uploads One Consent PDF per Delivery Group | D2: High | E2: Admin signed in; a POS order with more than one delivery group | F2: 1. Upload a consent-of-delivery PDF to one group 2. Upload a different PDF to another group 3. Inspect both | G2: Each group holds its own consent PDF and the two are independent | H2: Not Tested | I2: Functional
A3: Functional | B3: TC-Consent-02 | C3: Business Previews and Downloads Its Own Consent PDF | D3: High | E3: A consent PDF uploaded against the business's order | F3: 1. Open POS Order details as the business user 2. Preview the PDF 3. Download it | G3: Preview and download both succeed and the file matches what admin uploaded | H3: Not Tested | I3: Functional
A4: Functional | B4: TC-Consent-03 | C4: Business Access Is Read-Only | D4: High | E4: A consent PDF attached to the business's order | F4: 1. Look for upload, replace and remove controls as a business user 2. Attempt each action directly against the API | G4: No write control is offered and every direct write attempt is refused; attachment write is admin-only | H4: Not Tested | I4: Negative
A5: Validation | B5: TC-Consent-04 | C5: Only PDF Files Are Accepted | D5: High | E5: Admin upload dialog open | F5: 1. Attempt to upload a JPG, a PNG, a DOCX and an executable 2. Upload a valid PDF | G5: Every non-PDF is rejected with a clear message; the PDF is accepted | H5: Not Tested | I5: Negative
A6: Validation | B6: TC-Consent-05 | C6: File Larger Than 10 MB Is Rejected | D6: High | E6: Admin upload dialog open | F6: 1. Upload a PDF just under 10 MB 2. Upload one just over 10 MB | G6: The under-limit file is accepted; the over-limit file is rejected with a message naming the limit | H6: Not Tested | I6: Negative
A7: Security | B7: TC-Consent-06 | C7: A File Renamed to .pdf Is Rejected | D7: High | E7: A non-PDF file renamed with a .pdf extension | F7: 1. Attempt to upload it | G7: It is rejected; validation is on file content, not on the extension alone | H7: Not Tested | I7: Negative
A8: Security | B8: TC-Consent-07 | C8: Business Cannot Access Another Business's Consent PDF | D8: High | E8: Two businesses each with an order carrying a consent PDF | F8: 1. As one business, request the other's attachment by direct reference and by guessed identifier | G8: Access is refused with no leakage of the other business's file name, size or existence | H8: Not Tested | I8: Security
A9: Security | B9: TC-Consent-08 | C9: Download Link Is Not Publicly Guessable or Shareable | D9: High | E9: A consent PDF attached to an order | F9: 1. Obtain the download URL 2. Request it unauthenticated and from a different account | G9: Both are refused; the attachment is account-scoped and not served to an unauthenticated caller | H9: Not Tested | I9: Security
A10: Functional | B10: TC-Consent-09 | C10: Replacing a Consent PDF Keeps One Current File per Group | D10: Medium | E10: A group with an existing consent PDF | F10: 1. Upload a replacement 2. Inspect the group | G10: The group holds exactly one current consent PDF and the replacement is the one served | H10: Not Tested | I10: Edge / Boundary
A11: Functional | B11: TC-Consent-10 | C11: Removing a Consent PDF | D11: Medium | E11: A group with a consent PDF | F11: 1. Remove it as admin 2. Open the order as the business user | G11: The attachment is removed and the business surface shows an absent-attachment state rather than a broken link | H11: Not Tested | I11: Functional
A12: Audit | B12: TC-Consent-11 | C12: Add, Replace and Remove Are All Audit-Logged | D12: High | E12: Audit log accessible | F12: 1. Add, replace and remove a consent PDF 2. Inspect the audit log for each | G12: All three actions are logged with actor, action, target group and timestamp | H12: Not Tested | I12: Security
... A19: Non-Functional | B19: TC-Consent-18 | C19: Attachment Storage Meets Access and Retention Controls | D19: High | E19: A stored consent PDF | F19: 1. Inspect storage encryption, access control and retention configuration | G19: The file is stored under the applicable encryption, access-control and retention requirements | H19: Not Tested | I19: Security

Sheet Device Management Impl
A1: Subtopic / Category | B1: TC ID | C1: Title | D1: Priority | E1: Preconditions | F1: Steps | G1: Expected Result | H1: Status | I1: Test Type
A2: Backend | B2: TC-DevImpl-01 | C2: Device Record Created From a TID Mapping Event | D2: High | E2: The EMI-5719 order flow able to map a TID | F2: 1. Complete a TID mapping 2. Query the device record | G2: A device record is created from the mapping event carrying its provenance; the backend consumes the event and does not own the mapping | H2: Not Tested | I2: Contract / API
A3: Backend | B3: TC-DevImpl-02 | C3: Device Record Updated From a Termination Event | D3: High | E3: An active device and the EMI-5719 termination flow | F3: 1. Complete a termination 2. Query the device record | G3: The device record is updated to the terminated state from the event, and the device and its ledger remain readable | H3: Not Tested | I3: Contract / API
A4: Backend | B4: TC-DevImpl-03 | C4: Device Directory API Returns All Devices for Admin | D4: High | E4: Devices across several businesses; admin credentials | F4: 1. Call the device directory API as admin | G4: Every mapped device across all businesses is returned with pagination | H4: Not Tested | I4: Contract / API
A5: Backend | B5: TC-DevImpl-04 | C5: Device Directory API Is Account-Scoped for Business | D5: High | E5: Devices across several businesses; business credentials | F5: 1. Call the device directory API as a business user 2. Attempt to widen the scope through query parameters | G5: Only the caller's own devices are returned and the scope cannot be widened from the request | H5: Not Tested | I5: Contract / API
A6: Backend | B6: TC-DevImpl-05 | C6: Device Detail API Enforces the Same Scope | D6: High | E6: A device belonging to another business | F6: 1. Request its detail as a business user by direct identifier | G6: Refused with 403 or not-found and no detail leaks | H6: Not Tested | I6: Security
A7: Backend | B7: TC-DevImpl-06 | C7: Lifecycle Transitions Are Enforced Server-Side | D7: High | E7: A device in each lifecycle state | F7: 1. Attempt every transition permitted and forbidden by the status model, directly against the API | G7: Permitted transitions succeed and forbidden ones are refused with the allowed next states, regardless of what the client offers | H7: Not Tested | I7: Negative
A8: Backend | B8: TC-DevImpl-07 | C8: Every Lifecycle Action Is Audited | D8: High | E8: Audit log accessible | F8: 1. Perform each lifecycle action 2. Inspect the audit records | G8: Each action writes an audit record with identity, action, reason where required, and timestamp | H8: Not Tested | I8: Contract / API
A9: Sub-Ledger | B9: TC-DevImpl-08 | C9: Sub-Ledger API Returns Entries Tagged With the Device | D9: High | E9: A wallet with transactions carrying device metadata | F9: 1. Call the sub-ledger API for a device | G9: Only wallet-ledger entries tagged with that device's tid or deviceRef are returned, with a running balance | H9: Not Tested | I9: Functional
A10: Sub-Ledger | B10: TC-DevImpl-09 | C10: Sub-Ledger Is Read-Only From This Surface | D10: High | E10: A device with a sub-ledger balance | F10: 1. Attempt every write and money-movement operation against the sub-ledger API | G10: All are refused; the sub-ledger is a projection and the wallet ledger stays the single source of truth | H10: Not Tested | I10: Negative
A11: Sub-Ledger | B11: TC-DevImpl-10 | C11: Sub-Ledger Pagination and Date Range | D11: Medium | E11: A device with a long transaction history | F11: 1. Page through the sub-ledger and apply a date range | G11: Paging is stable with no duplicated or skipped entries, and the date range is honoured | H11: Not Tested | I11: Integration
A12: Web Business | B12: TC-DevImpl-11 | C12: Business Web My-Devices List and Detail | D12: High | E12: Business user on Web with devices | F12: 1. Open My Devices and then a device detail | G12: Only the business's own devices are listed; detail shows profile, status history and sub-ledger | H12: Not Tested | I12: Functional
... A21: Non-Functional | B21: TC-DevImpl-20 | C21: Directory and Sub-Ledger Load Within Budget | D21: High | E21: A production-scale device population and a device with 12 months of activity | F21: 1. Load the admin device list and a 12-month sub-ledger and time both | G21: The list loads within 2 seconds and the 12-month statement renders within 3 seconds | H21: Not Tested | I21: Performance / NFR

Sheet RBAC Roles & Groups
A1: Subtopic / Category | B1: TC ID | C1: Title | D1: Priority | E1: Preconditions | F1: Steps | G1: Expected Result | H1: Status | I1: Test Type
A2: Backend | B2: TC-RBAC-01 | C2: New Role and Group Model Is Exposed by the Redesigned APIs | D2: High | E2: Backend redesign deployed | F2: 1. Call the group, role and privilege endpoints 2. Compare the payloads against the documented model | G2: The endpoints expose the new role and group model with GroupDto, RoleDto and PrivilegeDto shapes as documented | H2: Not Tested | I2: Security
A3: Backend | B3: TC-RBAC-02 | C3: Business-Scoped Endpoints Return Only the Caller's Scope | D3: High | E3: Two businesses each with custom groups and roles | F3: 1. Call the business-scoped group and role endpoints as one business 2. Attempt to widen the scope through parameters | G3: Only the caller's own groups and roles are returned and the scope cannot be widened from the request | H3: Not Tested | I3: Contract / API
A4: Backend | B4: TC-RBAC-03 | C4: Admin-Scoped Endpoints Cover the Whole Platform | D4: High | E4: Admin credentials | F4: 1. Call the admin-scoped RBAC endpoints | G4: Admin-scoped data is returned across the platform, distinct from the business-scoped surface | H4: Not Tested | I4: Contract / API
A5: Backend | B5: TC-RBAC-04 | C5: Paged List Envelope Is Correct | D5: Medium | E5: Many groups and roles configured | F5: 1. Page through the list endpoints | G5: The page envelope is returned as documented, and paging is stable with no duplicated or skipped records | H5: Not Tested | I5: Integration
A6: Backend | B6: TC-RBAC-05 | C6: Privilege Assignment Is Enforced at the API, Not Only Hidden in the UI | D6: High | E6: A user lacking a given privilege | F6: 1. Call the endpoint that privilege guards, directly | G6: Refused with 403; enforcement is server-side and hiding the control in the UI is not the control | H6: Not Tested | I6: Security
A7: Backend | B7: TC-RBAC-06 | C7: Migration or Compatibility Path Is Documented and Honoured | D7: High | E7: Groups and roles created before the redesign | F7: 1. Read the documented migration requirements 2. Exercise the pre-existing groups and roles after the change | G7: Existing assignments behave as the migration document states; no user silently gains or loses access | H7: Not Tested | I7: Contract / API
A8: Web Business | B8: TC-RBAC-07 | C8: Business Web Group Management Against the New Endpoints | D8: High | E8: Business user on Web with group management privilege | F8: 1. Create, edit, list and delete a custom group 2. Inspect the calls made | G8: All operations succeed against the business-scoped group endpoints and the UI reflects the results | H8: Not Tested | I8: Functional
A9: Web Business | B9: TC-RBAC-08 | C9: Business Web Role and Privilege Management | D9: High | E9: Business user on Web with role management privilege | F9: 1. Create a role, assign privileges to it, then assign the role to a group | G9: All operations succeed against the business-scoped role and privilege endpoints and take effect for the assigned users | H9: Not Tested | I9: Security
A10: Web Admin | B10: TC-RBAC-09 | C10: Admin Web Manages Admin-Scoped Roles and Groups | D10: High | E10: Admin on Web | F10: 1. Manage admin-scoped groups, roles and privileges | G10: Operations succeed against the admin-scoped endpoints and are kept separate from the business-scoped surface | H10: Not Tested | I10: Security
A11: Platform | B11: TC-RBAC-10 | C11: Android Business RBAC Flows Adapted | D11: High | E11: Business user on Android | F11: 1. Exercise group, role and privilege flows | G11: All work against the new business-scoped endpoints with the new request and response models | H11: Not Tested | I11: Security
A12: Platform | B12: TC-RBAC-11 | C12: iOS Business RBAC Flows Adapted | D12: High | E12: Business user on iOS | F12: 1. Exercise group, role and privilege flows | G12: All work against the new business-scoped endpoints with the new request and response models | H12: Not Tested | I12: Security
... A21: Non-Functional | B21: TC-RBAC-20 | C21: Privilege Resolution Does Not Degrade Sign-In Latency | D21: Medium | E21: A user in many groups with many privileges | F21: 1. Measure sign-in and first-screen latency | G21: Latency stays within the normal budget as group and privilege counts grow | H21: Not Tested | I21: Performance / NFR

Sheet Registration Refresh Token
A1: Subtopic / Category | B1: TC ID | C1: Title | D1: Priority | E1: Preconditions | F1: Steps | G1: Expected Result | H1: Status | I1: Test Type
A2: Contract | B2: TC-RegRef-01 | C2: Verify OTP Response Parsed With the New Shape | D2: High | E2: Registration in progress at the OTP verification step | F2: 1. Complete OTP verification 2. Inspect how the response is parsed | G2: sessionToken and refreshToken are parsed as objects carrying token and expirationDuration; the client does not expect the old flat shape | H2: Not Tested | I2: Contract / API
A3: Contract | B3: TC-RegRef-02 | C3: Mobile OTP Response Handles Nullable Token Objects | D3: High | E3: A registration where otpRequired is returned false | F3: 1. Call the mobile OTP step 2. Inspect the parsed response | G3: sessionToken and refreshToken are present and parsed when otpRequired is false, and their absence is handled without error when it is true | H3: Not Tested | I3: Contract / API
A4: Contract | B4: TC-RegRef-03 | C4: expirationDuration Is Treated as Milliseconds | D4: High | E4: A registration session with a known expiry | F4: 1. Read expirationDuration and compute the refresh moment 2. Observe when the client refreshes | G4: The value is interpreted in milliseconds; the refresh fires before expiry rather than far too early or too late | H4: Not Tested | I4: Contract / API
A5: Functional | B5: TC-RegRef-04 | C5: Session Is Refreshed Before It Expires | D5: High | E5: An in-progress registration approaching session expiry | F5: 1. Hold the registration open past the original session lifetime 2. Observe the refresh call and continue the flow | G5: The refresh endpoint is called before expiry and the registration continues without restarting | H5: Not Tested | I5: Integration
A6: Functional | B6: TC-RegRef-05 | C6: Refresh Request Carries Both Credentials Correctly | D6: High | E6: An active registration session | F6: 1. Capture the refresh request | G6: The current session token is sent as Authorization Bearer and the refresh token in the refreshToken header | H6: Not Tested | I6: Functional
A7: Functional | B7: TC-RegRef-06 | C7: Refreshed Session Continues the Same Registration | D7: High | E7: A registration mid-flow with entered data | F7: 1. Let the session refresh 2. Continue to the next step | G7: The same registration continues with its data intact; the user is not returned to the start | H7: Not Tested | I7: Functional
A8: Isolation | B8: TC-RegRef-07 | C8: Registration Refresh Runs in Isolation From Login Refresh | D8: High | E8: A device with both an active login session and an in-progress registration | F8: 1. Let the registration session refresh 2. Inspect the login session and its token store | G8: The two mechanisms are isolated; neither refresh disturbs the other's tokens or triggers the other's flow | H8: Not Tested | I8: Integration
A9: Negative | B9: TC-RegRef-08 | C9: Invalid Refresh Token Is Rejected and Registration Can Restart | D9: High | E9: An in-progress registration | F9: 1. Corrupt the refresh token and let the refresh fire 2. Observe the client | G9: The refresh is rejected, the user is told clearly, and restarting registration works | H9: Not Tested | I9: Integration
A10: Negative | B10: TC-RegRef-09 | C10: Expired Refresh Token Is Rejected | D10: High | E10: A registration whose refresh token has expired | F10: 1. Let the refresh fire | G10: Rejected; the client does not loop retrying and the user can restart | H10: Not Tested | I10: Integration
A11: Negative | B11: TC-RegRef-10 | C11: Refresh Without an Active Registration Session Is Refused | D11: High | E11: A valid refresh token with no active session | F11: 1. Call the refresh endpoint | G11: Refused; the endpoint requires an active registration session | H11: Not Tested | I11: Negative
A12: Negative | B12: TC-RegRef-11 | C12: Refresh Failure Mid-Step Does Not Lose Entered Data Silently | D12: Medium | E12: A registration with data entered on the current step | F12: 1. Force the refresh to fail 2. Observe the client | G12: The user is told what happened rather than the screen resetting or hanging with no explanation | H12: Not Tested | I12: Negative
... A17: Platform | B17: TC-RegRef-16 | C17: Backgrounding the App Across the Refresh Window | D17: High | E17: An in-progress registration on Android and on iOS | F17: 1. Background the app across the refresh moment 2. Return to the app and continue | G17: The session is refreshed or refreshes on resume; the registration continues without restart on both platforms | H17: Not Tested | I17: Integration

Sheet ANB Settlement Files
A1: Subtopic / Category | B1: TC ID | C1: Title | D1: Priority | E1: Preconditions | F1: Steps | G1: Expected Result | H1: Status | I1: Test Type
A2: PTS Fetch | B2: TC-ANB-01 | C2: Job Runs on the Configured Schedule | D2: High | E2: PTS fetch job configured with a schedule | F2: 1. Let the schedule fire 2. Inspect the run record | G2: The job runs at the configured time and records its execution; the schedule is configuration, not code | H2: Not Tested | I2: Integration
A3: PTS Fetch | B3: TC-ANB-02 | C3: Configurable Current and Look-Back Dates Are Honoured | D3: High | E3: A look-back window configured | F3: 1. Set current and look-back dates 2. Run the job 3. Inspect which dates were pulled | G3: The job pulls exactly the configured current date and look-back range | H3: Not Tested | I3: Edge / Boundary
A4: PTS Fetch | B4: TC-ANB-03 | C4: Per-Date Cursor Advances Only After Successful Ingestion | D4: High | E4: A date whose ingestion can be made to fail | F4: 1. Force the ingestion to fail for a date 2. Inspect the cursor 3. Fix and re-run | G4: The cursor does not advance on failure and advances only after successful validation and ingestion | H4: Not Tested | I4: Negative
A5: PTS Fetch | B5: TC-ANB-04 | C5: Re-Reading a File or Date Creates No Duplicates | D5: High | E5: A date already ingested | F5: 1. Re-read the same file 2. Re-run the same date 3. Count the records | G5: No duplicate records are created by either action | H5: Not Tested | I5: Integration
A6: PTS Fetch | B6: TC-ANB-05 | C6: Malformed Input Is Rejected Without Partial Ingestion | D6: High | E6: A structurally malformed PTS file | F6: 1. Run the job over it 2. Inspect the persisted records | G6: The file is rejected and nothing from it is persisted; there is no half-ingested date | H6: Not Tested | I6: Negative
A7: PTS Fetch | B7: TC-ANB-06 | C7: Changed Closed Slip Is Frozen and Alarmed | D7: High | E7: A previously ingested closed slip that arrives changed | F7: 1. Deliver the changed slip 2. Inspect the stored record and the alarm channel | G7: The existing record is frozen rather than overwritten and an alarm is raised | H7: Not Tested | I7: Integration
A8: PTS Fetch | B8: TC-ANB-07 | C8: Missing Transactions Are Backfilled Through the Shared Flow | D8: High | E8: A PTS file containing transactions absent from our records | F8: 1. Run the job 2. Trace how the missing transactions are created | G8: They are backfilled through the shared transaction-processing flow, not through a bespoke insert path | H8: Not Tested | I8: Integration
A9: PTS Fetch | B9: TC-ANB-08 | C9: Lineage and Fee Information Are Retained | D9: High | E9: An ingested PTS file | F9: 1. Inspect a resulting record | G9: TR_SLIP, source-file lineage, applicable fee information and execution audit data are all retained and queryable | H9: Not Tested | I9: Integration
A10: MT940 | B10: TC-ANB-09 | C10: Matching Uses Exact Reference Equality Only | D10: High | E10: An MT940 credit and a PTS settlement group | F10: 1. Run matching 2. Trace the comparison performed | G10: Matching is on exact TR_SLIP or batch-reference equality; no amount, date, partial or fuzzy comparison is attempted at any point | H10: Not Tested | I10: Integration
A11: MT940 | B11: TC-ANB-10 | C11: No Fallback Matching When the Reference Does Not Match | D11: High | E11: An MT940 credit whose reference matches nothing but whose amount and date match a group exactly | F11: 1. Run matching | G11: No match is made; the credit is parked. A near-miss on amount and date must never produce a match | H11: Not Tested | I11: Integration
A12: MT940 | B12: TC-ANB-11 | C12: Statement Amount Validated Against the Expected Group Amount | D12: High | E12: A matched reference whose statement amount differs from the settlement group amount | F12: 1. Run matching 2. Inspect the outcome | G12: The mismatch is detected and reported as an exception rather than accepted | H12: Not Tested | I12: Integration
... A25: Non-Functional | B25: TC-ANB-24 | C25: Job Failure Mid-File Is Resumable | D25: High | E25: A large file with ingestion interrupted part-way | F25: 1. Interrupt the run 2. Re-run the job | G25: The run resumes or restarts cleanly with no duplicate and no partially ingested date left behind | H25: Not Tested | I25: Integration

Sheet PoS Gateway Integration
A1: Subtopic / Category | B1: TC ID | C1: Title | D1: Priority | E1: Preconditions | F1: Steps | G1: Expected Result | H1: Status | I1: Test Type
A2: Architecture | B2: TC-Gateway-01 | C2: Gateway Is a Separate Deployable Component | D2: High | E2: The deployed environment | F2: 1. Inspect the deployment topology | G2: The POS Integration Gateway is deployed as its own component, not embedded in Payment Orchestrator or another business service | H2: Not Tested | I2: Architecture
A3: Architecture | B3: TC-Gateway-02 | C3: Gateway Is the Only Ingress for the Partner Feed | D3: High | E3: The partner transaction feed | F3: 1. Attempt to submit the partner feed directly to Payment Orchestrator and to other internal services | G3: Only the gateway accepts the feed; every other ingress refuses it | H3: Not Tested | I3: Architecture
A4: Architecture | B4: TC-Gateway-03 | C4: No POS XML Handling Exists Outside the Gateway | D4: High | E4: Access to the internal services | F4: 1. Search Payment Orchestrator and other internal services for POS XML parsing or handling | G4: None exists; XML handling is confined to the gateway | H4: Not Tested | I4: Architecture
A5: Auth | B5: TC-Gateway-04 | C5: Unauthenticated Request Is Refused | D5: High | E5: Gateway endpoint reachable | F5: 1. Submit a well-formed request with no credentials | G5: Refused; every inbound POS request must be authenticated and authorised | H5: Not Tested | I5: Security
A6: Auth | B6: TC-Gateway-05 | C6: Invalid API Key or Client ID Is Refused | D6: High | E6: Gateway endpoint reachable | F6: 1. Submit with a wrong API key, then a wrong client id | G6: Both are refused without processing the payload | H6: Not Tested | I6: Negative
A7: Auth | B7: TC-Gateway-06 | C7: Expired or Reused JWT Is Refused | D7: High | E7: A short-TTL one-time-use JWT | F7: 1. Submit with an expired JWT 2. Submit twice with the same valid JWT | G7: The expired token is refused; the second use of a one-time token is refused | H7: Not Tested | I7: Negative
A8: Auth | B8: TC-Gateway-07 | C8: Mutual TLS Is Enforced | D8: High | E8: mTLS configured | F8: 1. Connect without a client certificate 2. Connect with an untrusted certificate 3. Connect with the partner certificate | G8: Only the trusted partner certificate is accepted | H8: Not Tested | I8: Security
A9: Auth | B9: TC-Gateway-08 | C9: Partner IP Allowlisting Is Enforced | D9: High | E9: IP allowlist configured | F9: 1. Submit a fully valid request from an address outside the allowlist | G9: Refused despite otherwise valid credentials | H9: Not Tested | I9: Security
A10: Auth | B10: TC-Gateway-09 | C10: Invalid HMAC Signature Is Refused | D10: High | E10: HMAC signing configured | F10: 1. Submit with a missing signature, then a signature computed over altered content | G10: Both are refused; the signature must be valid over the raw payload | H10: Not Tested | I10: Security
A11: Auth | B11: TC-Gateway-10 | C11: Replay Protection Blocks a Repeated Authenticated Request | D11: High | E11: A valid signed request already processed | F11: 1. Replay the identical authenticated request | G11: It is not processed a second time; replay protection refuses it | H11: Not Tested | I11: Security
A12: Validation | B12: TC-Gateway-11 | C12: XML Is Validated Against the Partner Schema Before Any Processing | D12: High | E12: The agreed mada Transaction Archive schema | F12: 1. Submit a payload that violates the schema 2. Trace where validation occurs relative to transformation | G12: Validation happens before any transformation or business processing and the payload is rejected there | H12: Not Tested | I12: Integration
... A33: Sensitive Data | B33: TC-Gateway-32 | C33: Sensitive Data Never Reaches Generic Application Logs | D33: High | E33: A processed transaction carrying card data | F33: 1. Inspect the generic application logs | G33: No masked or unmasked card data, EMV data or archived sensitive content appears in generic logs | H33: Not Tested | I33: Security

Sheet Admin POS Surfaces
A1: Subtopic / Category | B1: TC ID | C1: Title | D1: Priority | E1: Preconditions | F1: Steps | G1: Expected Result | H1: Status | I1: Test Type
A2: Device Txns | B2: TC-AdminPos-01 | C2: Admin Views POS Transactions Across All Devices | D2: High | E2: POS transactions across several devices and businesses; admin signed in | F2: 1. Open the POS Device Transactions view | G2: A paginated list of POS transactions across all devices is shown | H2: Not Tested | I2: Functional
A3: Device Txns | B3: TC-AdminPos-02 | C3: Admin Filters or Navigates to a Selected Device or TID | D3: High | E3: A populated transaction list | F3: 1. Filter by TID, then navigate from a device to its transactions | G3: Only that device's transactions are shown and the TID in view matches the selection | H3: Not Tested | I3: Functional
A4: Device Txns | B4: TC-AdminPos-03 | C4: Backend-Supported Filters Work With Pagination | D4: High | E4: A long transaction list | F4: 1. Apply a filter, then page through the results | G4: The filter persists across pages and paging is stable with no duplicated or skipped rows | H4: Not Tested | I4: Integration
A5: Device Txns | B5: TC-AdminPos-04 | C5: Filters Can Be Reset | D5: Medium | E5: Filters applied | F5: 1. Reset the filters | G5: The list returns to the unfiltered state and pagination resets with it | H5: Not Tested | I5: Functional
A6: Device Txns | B6: TC-AdminPos-05 | C6: Loading, Empty and Error States Are Handled | D6: High | E6: A slow response, an empty result and a failing endpoint | F6: 1. Trigger each condition | G6: A loading state is shown, an empty result shows an empty state rather than a blank grid, and a failure shows a controlled error with a retry | H6: Not Tested | I6: Negative
A7: ACH | B7: TC-AdminPos-06 | C7: Admin Views ACH Records Across All Devices | D7: High | E7: ACH records present; admin signed in | F7: 1. Open the ACH Records view | G7: A paginated list of ACH records across all devices is shown | H7: Not Tested | I7: Functional
A8: ACH | B8: TC-AdminPos-07 | C8: ACH Filters Including TID Apply and Reset | D8: High | E8: ACH records across several TIDs | F8: 1. Apply the backend-supported filters including TID 2. Reset them | G8: Filters return the correct subset where TID is available and reset restores the full list | H8: Not Tested | I8: Functional
A9: ACH | B9: TC-AdminPos-08 | C9: Only Backend-Permitted Actions Are Displayed | D9: High | E9: ACH records in states permitting different actions | F9: 1. Compare the actions shown per record against those the backend reports as available | G9: Only the actions the backend returns as available are displayed; the UI never offers an action the backend would refuse | H9: Not Tested | I9: Functional
A10: ACH | B10: TC-AdminPos-09 | C10: Release Requires Confirmation and Is Submitted Through the Backend | D10: High | E10: An ACH record with release available | F10: 1. Trigger release 2. Observe the confirmation step 3. Confirm and inspect the request | G10: A confirmation is required before submission and the action is performed through the backend, not simulated client-side | H10: Not Tested | I10: Functional
A11: ACH | B11: TC-AdminPos-10 | C11: Reject Requires Confirmation and Refreshes State | D11: High | E11: An ACH record with reject available | F11: 1. Trigger reject, confirm, and observe the record | G11: The record state refreshes after success and reflects what the backend returns | H11: Not Tested | I11: Functional
A12: ACH | B12: TC-AdminPos-11 | C12: Cancelling a Confirmation Performs No Action | D12: High | E12: An ACH record with an action available | F12: 1. Trigger the action and cancel at the confirmation step 2. Inspect the record and the network calls | G12: No request is sent and the record is unchanged | H12: Not Tested | I12: Functional
... A17: Non-Functional | B17: TC-AdminPos-16 | C17: Large Result Sets Page Without Degradation | D17: Medium | E17: A production-scale volume of POS transactions and ACH records | F17: 1. Page deep into both lists and measure response time | G17: Paging stays responsive and the backend uses indexed access rather than scanning | H17: Not Tested | I17: Performance / NFR

Sheet Transaction Amounts & Fees
A1: Subtopic / Category | B1: TC ID | C1: Title | D1: Priority | E1: Preconditions | F1: Steps | G1: Expected Result | H1: Status | I1: Test Type
A2: Amount Calc | B2: TC-Amount-01 | C2: Base Transaction Amount Includes Commission and VAT | D2: High | E2: An applicable transaction type with commission and VAT configured | F2: 1. Complete a transaction 2. Read the amount stored in the Base Transaction table | G2: The stored amount equals transaction amount plus commission amount plus VAT amount | H2: Not Tested | I2: Functional
A3: Amount Calc | B3: TC-Amount-02 | C3: Transaction Log Carries the Correct Amount | D3: High | E3: A completed applicable transaction | F3: 1. Read the transaction log entry | G3: The log amount includes commission and VAT where applicable and agrees with the base transaction | H3: Not Tested | I3: Functional
A4: Amount Calc | B4: TC-Amount-03 | C4: External Party Receives the Amount It Is Expected to Receive | D4: High | E4: An applicable transaction routed to an external party | F4: 1. Capture the outbound request 2. Compare against the expected receivable amount | G4: The amount sent matches what the external party is expected to receive | H4: Not Tested | I4: Functional
A5: Amount Calc | B5: TC-Amount-04 | C5: HyperPay Integration Amount Is Correct | D5: High | E5: A transaction routed through HyperPay | F5: 1. Complete it and compare the amount at every hop | G5: The amount is consistent across base transaction, transaction log and the HyperPay request | H5: Not Tested | I5: Functional
A6: Amount Calc | B6: TC-Amount-05 | C6: Bank Integration Amount Is Correct | D6: High | E6: A transaction routed to the bank | F6: 1. Complete it and compare the amount at every hop | G6: The amount is consistent across base transaction, transaction log and the bank request | H6: Not Tested | I6: Functional
A7: Amount Calc | B7: TC-Amount-06 | C7: OTC Integration Amount Is Correct | D7: High | E7: A transaction routed through OTC | F7: 1. Complete it and compare the amount at every hop | G7: The amount is consistent across base transaction, transaction log and the OTC request | H7: Not Tested | I7: Functional
A8: Amount Calc | B8: TC-Amount-07 | C8: Cash-Out Is Not Affected by the Change | D8: High | E8: A Cash-Out transaction | F8: 1. Complete it and compare the calculation against the pre-change behaviour | G8: Cash-Out amount calculation is unchanged; commission and VAT are not folded into the stored amount | H8: Not Tested | I8: Functional
A9: Amount Calc | B9: TC-Amount-08 | C9: VIBAN Is Not Affected by the Change | D9: High | E9: A VIBAN transaction | F9: 1. Complete it and compare against the pre-change behaviour | G9: VIBAN amount calculation is unchanged | H9: Not Tested | I9: Functional
A10: Amount Calc | B10: TC-Amount-09 | C10: Commission and VAT Are Never Added Twice | D10: High | E10: An applicable transaction traced through its full flow | F10: 1. Trace the amount at initiation, ledger posting, external call and settlement 2. Compare against the expected single application | G10: Commission and VAT are applied exactly once; no stage adds them a second time | H10: Not Tested | I10: Integration
A11: Amount Calc | B11: TC-Amount-10 | C11: Every Applicable Transaction Type Is Covered | D11: High | E11: One transaction of each applicable type | F11: 1. Complete each type 2. Verify the amount rule on each | G11: Every applicable type follows the rule; the two documented exclusions are the only exceptions | H11: Not Tested | I11: Functional
A12: Amount Calc | B12: TC-Amount-11 | C12: Zero-Commission Configuration Still Computes Correctly | D12: Medium | E12: A transaction type with no commission or VAT configured | F12: 1. Complete a transaction | G12: The stored amount equals the transaction amount with no phantom fee added | H12: Not Tested | I12: Edge / Boundary
... A26: Regression | B26: TC-Amount-12 | C26: Existing Transactions Are Not Retrospectively Re-Priced | D26: High | E26: Transactions completed before the amount-calculation change | F26: 1. Re-read their base transaction and log amounts | G26: Historical amounts are unchanged; the new rule applies only to new transactions | H26: Not Tested | I26: Regression

Sheet Pending Reason & Rebuild Fix
A1: Subtopic / Category | B1: TC ID | C1: Title | D1: Priority | E1: Preconditions | F1: Steps | G1: Expected Result | H1: Status | I1: Test Type
A2: Reason | B2: TC-Reason-01 | C2: Reason Is Persisted Whenever a Transaction Is Left Pending | D2: High | E2: A transaction that will be left in a pending state | F2: 1. Drive it to pending 2. Read the reason on the base transaction | G2: The reason is persisted on the base transaction | H2: Not Tested | I2: Functional
A3: Reason | B3: TC-Reason-02 | C3: Reason Is Persisted for Every Pending Cause | D3: High | E3: Several distinct causes that leave a transaction pending | F3: 1. Drive a transaction to pending by each cause in turn 2. Read the reason each time | G3: Every cause persists a reason and each reason distinguishes its cause; none is left null or a generic placeholder | H3: Not Tested | I3: Functional
A4: Reason | B4: TC-Reason-03 | C4: Reason Survives Through to Settlement or Failure | D4: High | E4: A pending transaction that later settles, and another that later fails | F4: 1. Advance each to its terminal state 2. Read the record | G4: The pending reason remains available for audit after the transaction reaches its terminal state | H4: Not Tested | I4: Negative
A5: Reason | B5: TC-Reason-04 | C5: Reason Is Visible to Ops on the Pending Queue | D5: Medium | E5: Pending transactions of several causes | F5: 1. Open the Ops pending view | G5: The reason is displayed per transaction, so the cause is visible without opening the record | H5: Not Tested | I5: Functional
A6: Reason | B6: TC-Reason-05 | C6: Reason Is Consistent With the Transaction Ledger Pending Entry | D6: High | E6: A pending POS transaction | F6: 1. Compare the base transaction reason with the transaction ledger pending entry reason | G6: The two agree; there is no divergence between the base transaction and the ledger view | H6: Not Tested | I6: Functional
A7: Rebuild Fix | B7: TC-RebuildFix-01 | C7: Rebuild Running Balance Completes Without the Reported Failure | D7: High | E7: The scenario that previously caused the rebuild to fail | F7: 1. Reproduce the scenario 2. Run the rebuild | G7: The rebuild completes; the previously reported failure does not recur | H7: Not Tested | I7: Negative
A8: Rebuild Fix | B8: TC-RebuildFix-02 | C8: Rebuilt Balances Match the Ledger-Derived Values | D8: High | E8: A wallet rebuilt after the fix | F8: 1. Compare the rebuilt balances against a ledger-derived recompute | G8: The two agree across all four buckets | H8: Not Tested | I8: Regression
A9: Rebuild Fix | B9: TC-RebuildFix-03 | C9: Rebuild Is Idempotent After the Fix | D9: High | E9: A completed rebuild over an unchanged ledger | F9: 1. Re-run the identical rebuild | G9: The second run makes no change; the fix did not reintroduce mutation on every execution | H9: Not Tested | I9: Integration
A10: Rebuild Fix | B10: TC-RebuildFix-04 | C10: Fix Does Not Alter Entry Ordering | D10: High | E10: A wallet with a known statement sequence | F10: 1. Rebuild and compare the entry sequence against the expected order | G10: Ordering is unchanged by the fix; the sequence is reproducible across runs | H10: Not Tested | I10: Regression
A11: Rebuild Fix | B11: TC-RebuildFix-05 | C11: Fix Is Consistent With the Newer Rebuild Design | D11: Medium | E11: The EMI-5945 statement rebuild criteria | F11: 1. Compare the fixed behaviour against the archive-then-replay design EMI-5945 defines | G11: The fix does not contradict the newer design. Any divergence is recorded so the two are reconciled rather than left to drift | H11: Not Tested | I11: Integration

Sheet Security & Logging
A1: Subtopic / Category | B1: TC ID | C1: Title | D1: Priority | E1: Preconditions | F1: Steps | G1: Expected Result | H1: Status | I1: Test Type
A2: OTP Hashing | B2: TC-Sec-01 | C2: OTP Is Hashed in the Notification Log | D2: High | E2: A notification carrying an OTP | F2: 1. Trigger it 2. Read the Notification Log collection in MongoDB | G2: The OTP is stored hashed; no plain-text OTP is present | H2: Not Tested | I2: Security
A3: OTP Hashing | B3: TC-Sec-02 | C3: OTP Is Hashed in the Taqnyat HTTP Log | D3: High | E3: A Taqnyat request carrying an OTP | F3: 1. Trigger it 2. Read the HTTP Log collection | G3: The OTP is stored hashed in the HTTP log | H3: Not Tested | I3: Security
A4: OTP Hashing | B4: TC-Sec-03 | C4: Only Taqnyat Stores OTP Data in the HTTP Log | D4: High | E4: Traffic across all integrations | F4: 1. Exercise Wathiq, Nafath, Yaqeen, Taqnyat, Lean, MOZN, HyperPay, WS1, WS3 and ANB 2. Search the HTTP Log for OTP-related content per integration | G4: Only Taqnyat carries OTP-related data, and it is hashed. Any other integration storing OTP data is a finding | H4: Not Tested | I4: Security
A5: OTP Hashing | B5: TC-Sec-04 | C5: Login Flow Stores No Plain-Text OTP | D5: High | E5: Login with OTP | F5: 1. Complete a login 2. Search both log collections for the OTP value | G5: No plain-text OTP is persisted anywhere | H5: Not Tested | I5: Security
A6: OTP Hashing | B6: TC-Sec-05 | C6: Registration Flow Stores No Plain-Text OTP | D6: High | E6: Registration with OTP | F6: 1. Complete a registration 2. Search both log collections | G6: No plain-text OTP is persisted | H6: Not Tested | I6: Security
A7: OTP Hashing | B7: TC-Sec-06 | C7: Top-Up and Bank Transfer Store No Plain-Text OTP | D7: High | E7: A top-up and a bank transfer, both OTP-verified | F7: 1. Complete both 2. Search both log collections | G7: No plain-text OTP is persisted for either | H7: Not Tested | I7: Security
A8: OTP Hashing | B8: TC-Sec-07 | C8: Every OTP-Verified Transaction Type Is Covered | D8: High | E8: One transaction of each type requiring OTP verification | F8: 1. Complete each 2. Search both log collections | G8: No transaction type leaves a plain-text OTP in either collection | H8: Not Tested | I8: Security
A9: OTP Hashing | B9: TC-Sec-08 | C9: Incoming Transaction Job Stores No Plain-Text OTP | D9: High | E9: The incoming transaction job running with OTP-bearing notifications | F9: 1. Let the job run 2. Search both log collections | G9: No plain-text OTP is persisted by the job path | H9: Not Tested | I9: Security
A10: OTP Hashing | B10: TC-Sec-09 | C10: Hash Is Not Trivially Reversible to the OTP | D10: High | E10: A hashed OTP in the log | F10: 1. Attempt to recover the OTP from the stored value by direct comparison against the small OTP keyspace | G10: The hashing approach does not make the short OTP keyspace trivially reversible. If it does, record it as a finding rather than passing the test | H10: Not Tested | I10: Security
A11: Lean | B11: TC-Lean-01 | C11: Auth Failure Throws LeanAuthenticationException With Its Code | D11: High | E11: Lean access-token call able to fail authentication | F11: 1. Force an auth failure 2. Inspect the exception and the returned error code | G11: LeanAuthenticationException is thrown and LEAN_AUTHENTICATION_FAILED is returned, not a raw or unhandled error | H11: Not Tested | I11: Negative
A12: Lean | B12: TC-Lean-02 | C12: Business Verification Failure Throws LeanVerificationException | D12: High | E12: verifyBusinessAccount able to fail | F12: 1. Force a verification failure | G12: LeanVerificationException is thrown and LEAN_VERIFICATION_FAILED is returned | H12: Not Tested | I12: Negative
... A24: Remediation | B24: TC-Sec-11 | C24: Remediation Introduced No Functional Regression | D24: High | E24: The remediated Android build | F24: 1. Run the core business flows: login, registration, transfer, bill payment, top-up | G24: All core flows work unchanged after the security remediation | H24: Not Tested | I24: Security

Sheet Localisation & Messages
A1: Subtopic / Category | B1: TC ID | C1: Title | D1: Priority | E1: Preconditions | F1: Steps | G1: Expected Result | H1: Status | I1: Test Type
A2: Locale | B2: TC-Locale-01 | C2: Response Language Follows the Requested Locale | D2: High | E2: Endpoints returning user-facing messages | F2: 1. Call a representative set with an Arabic locale, then an English locale | G2: Each returns messages in the requested language; nothing is pinned to a single hardcoded locale | H2: Not Tested | I2: Localisation
A3: Locale | B3: TC-Locale-02 | C3: No Hardcoded Locale Remains in the Audited Paths | D3: High | E3: The hardcoded-locale audit list produced by the task | F3: 1. Exercise each listed path in both locales | G3: Each resolves the locale dynamically; none returns a fixed language regardless of the request | H3: Not Tested | I3: Localisation
A4: Locale | B4: TC-Locale-03 | C4: Unsupported or Missing Locale Falls Back Predictably | D4: Medium | E4: Endpoints returning user-facing messages | F4: 1. Call with an unsupported locale, then with none at all | G4: A documented default is applied consistently rather than the response varying by endpoint | H4: Not Tested | I4: Negative
A5: Locale | B5: TC-Locale-04 | C5: Locale Is Honoured on Error Responses Too | D5: High | E5: An endpoint that returns a validation error | F5: 1. Force the error in each locale | G5: Error messages follow the requested locale, not only success messages | H5: Not Tested | I5: Localisation
A6: Messages | B6: TC-Msg-01 | C6: Every Database-Stored Exception Message Has an Arabic Translation | D6: High | E6: The list of exceptions using database-stored messages | F6: 1. Trigger or query each 2. Check the Arabic text | G6: Every listed message has Arabic coverage; any missing translation is recorded as a finding | H6: Not Tested | I6: Negative
A7: Messages | B7: TC-Msg-02 | C7: Every Database-Stored Exception Message Has an English Translation | D7: High | E7: The same list | F7: 1. Trigger or query each 2. Check the English text | G7: Every listed message has English coverage; gaps are recorded | H7: Not Tested | I7: Localisation
A8: Messages | B8: TC-Msg-03 | C8: No Message Falls Back to a Raw Key or Code | D8: High | E8: All database-stored messages in both locales | F8: 1. Render each in both locales | G8: No surface shows a raw translation key, an enum name or a bare error code to the user | H8: Not Tested | I8: Localisation
A9: Messages | B9: TC-Msg-04 | C9: Message Audit List Is Complete | D9: Medium | E9: The produced list of exceptions using database-stored messages | F9: 1. Cross-check the list against the exceptions actually reachable in the product | G9: The list covers every reachable database-stored message; an incomplete audit is itself a finding | H9: Not Tested | I9: Localisation
A10: Translations | B10: TC-Trans-01 | C10: Saudi Banking Language Guidelines Are Applied | D10: High | E10: The approved language guidelines | F10: 1. Review the Arabic wording across the main flows against the guidelines | G10: Wording follows the approved guidelines and reads correctly for the Saudi banking context | H10: Not Tested | I10: Localisation
A11: Translations | B11: TC-Trans-02 | C11: Common Terms Are Consistent Across the Application | D11: High | E11: A list of recurring terms such as balance, wallet, transfer, commission and VAT | F11: 1. Compare how each term is rendered across every screen that uses it | G11: Each term is rendered consistently everywhere; the shared common file is the single source for them | H11: Not Tested | I11: Localisation
A12: Translations | B12: TC-Trans-03 | C12: Screen-Specific Wording Is Preserved Where Needed | D12: Medium | E12: Screens whose wording is deliberately specific | F12: 1. Review those screens against the shared common wording | G12: Deliberately specific wording is retained rather than flattened into the shared term | H12: Not Tested | I12: Localisation
... A16: Translations | B16: TC-Trans-07 | C16: Interpolated Values Render Correctly in Both Locales | D16: High | E16: Messages carrying amounts, dates, names and counts | F16: 1. Render each in Arabic and English | G16: Placeholders are substituted correctly in both, with no reversed or misplaced values under RTL | H16: Not Tested | I16: Localisation

Sheet Customer App Updates
A1: Subtopic / Category | B1: TC ID | C1: Title | D1: Priority | E1: Preconditions | F1: Steps | G1: Expected Result | H1: Status | I1: Test Type
A2: BalanceCard | B2: TC-App-01 | C2: BalanceCard Owns Balance Fetch and Refresh | D2: High | E2: Android customer app on a screen hosting BalanceCard | F2: 1. Open the screen and observe where the balance fetch originates | G2: BalanceCard owns the fetch and refresh state; the host screen does not fetch the balance itself | H2: Not Tested | I2: Functional
A3: BalanceCard | B3: TC-App-02 | C3: Redundant Home Balance Fetch Is Removed | D3: High | E3: Android customer Home screen | F3: 1. Open Home and capture the network calls | G3: The balance is fetched once by BalanceCard; the previous duplicate Home fetch no longer occurs | H3: Not Tested | I3: Integration
A4: BalanceCard | B4: TC-App-03 | C4: Balance Refreshes on Return After a Successful Payment | D4: High | E4: A supported payment flow on Android customer | F4: 1. Complete a payment successfully and return to the host screen | G4: The balance refreshes automatically and reflects the completed payment | H4: Not Tested | I4: Functional
