Workbook

Sheet Overview
A1: Category | B1: Details
A2: Document Name | B2: PoS Transactions testcases
A3: Epic / Story Ref | B3: EMI-5914 PoS Transactions Epic (full epic coverage)
A4: Release Number | B4: V 6.6.0 / Sprint 74
A5: Environment | B5: UAT
A6: Testing Period | B6: Sprint Test Execution Cycle
A9: EMI-5914 PoS Transactions — Test Case Results by Category
A11: Category (Feature / Story) | B11: Passed | C11: Failed | D11: Partially Passed | E11: Not Tested | F11: Not Implemented | G11: Total Checks | H11: Pass Rate %
A12: EMI-5915 — Callback Ingestion & Validation | B12: =COUNTIF('Callback Ingestion & Valid'!H2:H200, "Passed") | C12: =COUNTIF('Callback Ingestion & Valid'!H2:H200, "Failed") | D12: =COUNTIF('Callback Ingestion & Valid'!H2:H200, "Partially Passed") | E12: =COUNTIF('Callback Ingestion & Valid'!H2:H200, "Not Tested") | F12: =COUNTIF('Callback Ingestion & Valid'!H2:H200, "Not Implemented") | G12: =SUM(B12:F12) | H12: =IF(G12>0, B12/G12, 0)
A13: EMI-5916 — Wallet Crediting & Visibility | B13: =COUNTIF('Wallet Crediting & Visib'!H2:H200, "Passed") | C13: =COUNTIF('Wallet Crediting & Visib'!H2:H200, "Failed") | D13: =COUNTIF('Wallet Crediting & Visib'!H2:H200, "Partially Passed") | E13: =COUNTIF('Wallet Crediting & Visib'!H2:H200, "Not Tested") | F13: =COUNTIF('Wallet Crediting & Visib'!H2:H200, "Not Implemented") | G13: =SUM(B13:F13) | H13: =IF(G13>0, B13/G13, 0)
A14: EMI-5917 — Wallet Payment at Terminal | B14: =COUNTIF('Wallet Payment at Terminal'!H2:H200, "Passed") | C14: =COUNTIF('Wallet Payment at Terminal'!H2:H200, "Failed") | D14: =COUNTIF('Wallet Payment at Terminal'!H2:H200, "Partially Passed") | E14: =COUNTIF('Wallet Payment at Terminal'!H2:H200, "Not Tested") | F14: =COUNTIF('Wallet Payment at Terminal'!H2:H200, "Not Implemented") | G14: =SUM(B14:F14) | H14: =IF(G14>0, B14/G14, 0)
A15: EMI-5918 — PoS Refunds | B15: =COUNTIF('PoS Refunds'!H2:H200, "Passed") | C15: =COUNTIF('PoS Refunds'!H2:H200, "Failed") | D15: =COUNTIF('PoS Refunds'!H2:H200, "Partially Passed") | E15: =COUNTIF('PoS Refunds'!H2:H200, "Not Tested") | F15: =COUNTIF('PoS Refunds'!H2:H200, "Not Implemented") | G15: =SUM(B15:F15) | H15: =IF(G15>0, B15/G15, 0)
A16: EMI-5919 — Void & Technical Reversal | B16: =COUNTIF('Void & Technical Reversal'!H2:H200, "Passed") | C16: =COUNTIF('Void & Technical Reversal'!H2:H200, "Failed") | D16: =COUNTIF('Void & Technical Reversal'!H2:H200, "Partially Passed") | E16: =COUNTIF('Void & Technical Reversal'!H2:H200, "Not Tested") | F16: =COUNTIF('Void & Technical Reversal'!H2:H200, "Not Implemented") | G16: =SUM(B16:F16) | H16: =IF(G16>0, B16/G16, 0)
A17: EMI-5920 — Reconciliation & Three-Way Match | B17: =COUNTIF('Recon & Three-Way Match'!H2:H200, "Passed") | C17: =COUNTIF('Recon & Three-Way Match'!H2:H200, "Failed") | D17: =COUNTIF('Recon & Three-Way Match'!H2:H200, "Partially Passed") | E17: =COUNTIF('Recon & Three-Way Match'!H2:H200, "Not Tested") | F17: =COUNTIF('Recon & Three-Way Match'!H2:H200, "Not Implemented") | G17: =SUM(B17:F17) | H17: =IF(G17>0, B17/G17, 0)
A18: EMI-5921 — PoS Commission Configuration | B18: =COUNTIF('PoS Commission Config'!H2:H200, "Passed") | C18: =COUNTIF('PoS Commission Config'!H2:H200, "Failed") | D18: =COUNTIF('PoS Commission Config'!H2:H200, "Partially Passed") | E18: =COUNTIF('PoS Commission Config'!H2:H200, "Not Tested") | F18: =COUNTIF('PoS Commission Config'!H2:H200, "Not Implemented") | G18: =SUM(B18:F18) | H18: =IF(G18>0, B18/G18, 0)
A19: EMI-5922 — ACH & VIBAN (per TID group) | B19: =COUNTIF('ACH & VIBAN per TID'!H2:H200, "Passed") | C19: =COUNTIF('ACH & VIBAN per TID'!H2:H200, "Failed") | D19: =COUNTIF('ACH & VIBAN per TID'!H2:H200, "Partially Passed") | E19: =COUNTIF('ACH & VIBAN per TID'!H2:H200, "Not Tested") | F19: =COUNTIF('ACH & VIBAN per TID'!H2:H200, "Not Implemented") | G19: =SUM(B19:F19) | H19: =IF(G19>0, B19/G19, 0)
A20: EMI-5923 — PoS Compliance Gates & Held Funds | B20: =COUNTIF('PoS Compliance Gates'!H2:H200, "Passed") | C20: =COUNTIF('PoS Compliance Gates'!H2:H200, "Failed") | D20: =COUNTIF('PoS Compliance Gates'!H2:H200, "Partially Passed") | E20: =COUNTIF('PoS Compliance Gates'!H2:H200, "Not Tested") | F20: =COUNTIF('PoS Compliance Gates'!H2:H200, "Not Implemented") | G20: =SUM(B20:F20) | H20: =IF(G20>0, B20/G20, 0)
A21: EMI-5989 — Settlement Grouping & Gate 1 | B21: =COUNTIF('Settlement Grouping & Gate 1'!H2:H200, "Passed") | C21: =COUNTIF('Settlement Grouping & Gate 1'!H2:H200, "Failed") | D21: =COUNTIF('Settlement Grouping & Gate 1'!H2:H200, "Partially Passed") | E21: =COUNTIF('Settlement Grouping & Gate 1'!H2:H200, "Not Tested") | F21: =COUNTIF('Settlement Grouping & Gate 1'!H2:H200, "Not Implemented") | G21: =SUM(B21:F21) | H21: =IF(G21>0, B21/G21, 0)
A22: EMI-5991 — PTS Retrieval & Parsing | B22: =COUNTIF('PTS Retrieval & Parsing'!H2:H200, "Passed") | C22: =COUNTIF('PTS Retrieval & Parsing'!H2:H200, "Failed") | D22: =COUNTIF('PTS Retrieval & Parsing'!H2:H200, "Partially Passed") | E22: =COUNTIF('PTS Retrieval & Parsing'!H2:H200, "Not Tested") | F22: =COUNTIF('PTS Retrieval & Parsing'!H2:H200, "Not Implemented") | G22: =SUM(B22:F22) | H22: =IF(G22>0, B22/G22, 0)
A23: EMI-6018 — ZATCA e-invoicing (Provisional) | B23: =COUNTIF('ZATCA e-invoicing'!H2:H200, "Passed") | C23: =COUNTIF('ZATCA e-invoicing'!H2:H200, "Failed") | D23: =COUNTIF('ZATCA e-invoicing'!H2:H200, "Partially Passed") | E23: =COUNTIF('ZATCA e-invoicing'!H2:H200, "Not Tested") | F23: =COUNTIF('ZATCA e-invoicing'!H2:H200, "Not Implemented") | G23: =SUM(B23:F23) | H23: =IF(G23>0, B23/G23, 0)
A24: EMI-5914 — End-to-End Business Flows | B24: =COUNTIF('E2E Business Flows'!H2:H200, "Passed") | C24: =COUNTIF('E2E Business Flows'!H2:H200, "Failed") | D24: =COUNTIF('E2E Business Flows'!H2:H200, "Partially Passed") | E24: =COUNTIF('E2E Business Flows'!H2:H200, "Not Tested") | F24: =COUNTIF('E2E Business Flows'!H2:H200, "Not Implemented") | G24: =SUM(B24:F24) | H24: =IF(G24>0, B24/G24, 0)
A25: Total | B25: =SUM(B12:B24) | C25: =SUM(C12:C24) | D25: =SUM(D12:D24) | E25: =SUM(E12:E24) | F25: =SUM(F12:F24) | G25: =SUM(G12:G24) | H25: =IF(G25>0, B25/G25, 0)
A27: Test Execution Statuses & Definitions
A28: Status | B28: Definition / Criteria | C28: Allowed In Workflow
A29: Passed | B29: All test steps executed with actual results fully conforming to expected acceptance criteria. | C29: Yes
A30: Failed | B30: One or more test steps failed or produced unexpected discrepancies/defects. | C30: Yes
A31: Partially Passed | B31: Core functionality works but secondary assertions or non-blocking edge cases encountered minor issues. | C31: Yes
A32: Not Tested | B32: Test case is ready for execution in current cycle but has not yet been executed. | C32: Yes (Default)
A33: Not Implemented | B33: Feature or endpoint dependency is currently in development / unreleased (e.g. provisional specs). | C33: Yes
A34: NA | B34: Scenario is not applicable to current deployment scope or hardware configuration. | C34: Yes

Sheet Coverage Matrix
A1: EMI Ticket | B1: Story / Scope | C1: Jira Status | D1: Sheet in This Workbook | E1: Test Cases | F1: Coverage
A2: EMI-5915 | B2: Callback Ingestion & Validation | C2: To Do | D2: Callback Ingestion & Valid | E2: 51 | F2: Covered
A3: EMI-5916 | B3: Wallet Crediting & Visibility | C3: To Do | D3: Wallet Crediting & Visib | E3: 35 | F3: Covered
A4: EMI-5917 | B4: Wallet Payment at Terminal | C4: To Do | D4: Wallet Payment at Terminal | E4: 42 | F4: Covered
A5: EMI-5918 | B5: PoS Refunds | C5: To Do | D5: PoS Refunds | E5: 40 | F5: Covered
A6: EMI-5919 | B6: Void & Technical Reversal | C6: To Do | D6: Void & Technical Reversal | E6: 19 | F6: Covered
A7: EMI-5920 | B7: Reconciliation & Three-Way Match | C7: To Do | D7: Recon & Three-Way Match | E7: 31 | F7: Covered
A8: EMI-5921 | B8: PoS Commission Configuration | C8: To Do | D8: PoS Commission Config | E8: 31 | F8: Covered
A9: EMI-5922 | B9: ACH & VIBAN (per TID group) | C9: To Do | D9: ACH & VIBAN per TID | E9: 95 | F9: Covered
A10: EMI-5923 | B10: PoS Compliance Gates & Held Funds | C10: To Do | D10: PoS Compliance Gates | E10: 18 | F10: Covered
A11: EMI-5989 | B11: Settlement Grouping & Gate 1 | C11: To Do | D11: Settlement Grouping & Gate 1 | E11: 29 | F11: Covered
A12: EMI-5991 | B12: PTS Retrieval & Parsing | C12: To Do | D12: PTS Retrieval & Parsing | E12: 36 | F12: Covered
A13: EMI-6018 | B13: ZATCA e-invoicing (Provisional) | C13: To Do | D13: ZATCA e-invoicing | E13: 12 | F13: Covered
... A26: EMI-5949 | B26: Transaction Lifecycle Ordering Guard (Task) | C26: To Do | D26: Balances & Wallet Consistency EMI-5944.xlsx | E26: 24 | F26: Covered - separate workbook

Sheet Callback Ingestion & Valid
A1: Subtopic / Category | B1: TC ID | C1: Title | D1: Priority | E1: Preconditions | F1: Steps | G1: Expected Result | H1: Status | I1: Test Type
A2: Functional | B2: TC-Callback-01 | C2: Valid Purchase Callback | D2: High | E2: Callback endpoint reachable; TID linked to an active wallet | F2: 1. Submit a well-formed PURCHASE callback with all mandatory canonical fields (event_type, provider_txn_id, tid, mid, instrument, status, amount, currency, occurred_at) | G2: ACCEPTED; PosTransaction created; origin=TXN_CALLBACK; wallet_id snapshotted | H2: NA | I2: Functional
A3: Functional | B3: TC-Callback-02 | C3: Persisted Record Integrity | D3: Medium | E3: A purchase callback has been accepted (see Valid Purchase Callback) | F3: 1. Query the stored PosTransaction record for the accepted callback 2. Compare stored STAN, RRN, TID, MID, amount and masked_pan against the source payload | G3: Stored STAN, RRN, TID, MID, amount, masked PAN, etc. match the source payload | H3: NA | I3: Functional
A4: Functional | B4: TC-Callback-03 | C4: Per-TID Ledger Entry Written on Acceptance | D4: Medium | E4: A purchase callback has been accepted | F4: 1. Query the stored transaction's ledger status/reason field | G4: Exactly one per-TID ledger entry (EMI-5915's booking pipeline output) is written for the accepted transaction; the entry carries the callback's status/reason; no wallet balance effect occurs at this point. | H4: NA | I4: Edge / Boundary
A5: Functional | B5: TC-Callback-04 | C5: Failed Callback Persistence | D5: Medium | E5: Callback endpoint available | F5: 1. Submit a callback that fails validation or processing (e.g. terminal rejection) 2. Query the base transaction/callback table | G5: Failed callback is recorded in the required base transaction/callback table with the correct failure reason | H5: NA | I5: Negative
A6: Functional | B6: TC-Callback-05 | C6: Masked Archive & Retention (All Outcomes) | D6: Medium | E6: Ingestion log/archive accessible | F6: 1. Submit callbacks producing each outcome (ACCEPTED, TERMINAL, RETRYABLE, UNMATCHED, COMPLIANCE_HOLD, DUPLICATE) 2. Inspect the archived record for each outcome | G6: Every outcome type is archived masked with 7-year retention; no plaintext PAN appears in any archived record | H6: NA | I6: Integration
A7: Functional | B7: TC-Callback-06 | C7: wallet_id Snapshot Immutability | D7: Medium | E7: TID currently linked to a wallet | F7: 1. Submit an accepted callback for a linked TID 2. Re-link the TID to a different wallet in the registry 3. Query the original transaction's wallet_id | G7: wallet_id is snapshotted immutably at TID resolution time and does not change even if the TID's wallet link changes afterward | H7: NA | I7: Functional
A8: Functional | B8: TC-Callback-07 | C8: Direct Pipeline Invocation — Valid Booking | D8: High | E8: Shared booking pipeline exposed as a callable service entry point; a valid, well-formed transaction payload | F8: 1. Invoke the pipeline directly as EMI-5991 would, with origin=RECON_BACKFILL, for a valid transaction | G8: Transaction is validated, resolved, passed through Gate 1, and booked identically to the callback path; origin=RECON_BACKFILL is set; no branch bypasses a control | H8: NA | I8: Functional
A9: Functional | B9: TC-Callback-08 | C9: Direct Pipeline Invocation — Unknown TID | D9: High | E9: Shared booking pipeline exposed as a callable service entry point; TID with no wallet mapping | F9: 1. Invoke the pipeline directly as EMI-5991 would, with origin=RECON_BACKFILL, for a transaction whose TID is unknown/unregistered | G9: Transaction is accepted and parked UNMATCHED with Ops alarm, identical to the callback path; origin=RECON_BACKFILL is set | H9: NA | I9: Negative
A10: Functional | B10: TC-Callback-09 | C10: Direct Pipeline Invocation — Gate 1 Hold | D10: High | E10: Shared booking pipeline exposed as a callable service entry point; wallet flagged for AML/sanctions/SAMA breach | F10: 1. Invoke the pipeline directly as EMI-5991 would, with origin=RECON_BACKFILL, for a transaction that should trigger a Gate 1 hold | G10: Gate 1 produces COMPLIANCE_HOLD with no wallet ledger entries, identical to the callback path; no branch bypasses the compliance gate | H10: NA | I10: Functional
A11: Functional | B11: TC-Callback-10 | C11: Callback Header Validation | D11: Medium | E11: Published integration contract defines required headers | F11: 1. Submit a valid payload with a missing or incorrect required header (e.g. Content-Type, Accept-Language) | G11: Invalid/missing required headers are rejected according to the agreed integration contract | H11: NA | I11: Negative
A12: Functional | B12: TC-Callback-11 | C12: Empty/Malformed Request | D12: Medium | E12: Ingestion endpoint available | F12: 1. Submit a POST with an empty body 2. Submit a structurally broken/malformed transport payload | G12: Empty body or malformed transport payload returns a controlled validation error, not HTTP 500/unhandled exception | H12: NA | I12: Negative
... A52: Lifecycle / Registry | B52: TC-Callback-51 | C52: Status Transition on Failure | D52: High | E52: Active TID in terminal registry; background connectivity evaluation job running | F52: 1. Keep terminal disconnected for prolonged period (e.g. 24h). 2. Allow scheduled registry evaluation job to execute. 3. Inspect terminal record status. | G52: A terminal that fails to report for a prolonged period (e.g., 24h) is automatically moved to a "Connectivity Review" status in the registry. | H52: NA | I52: Negative

Sheet Wallet Crediting & Visib
A1: Subtopic / Category | B1: TC ID | C1: Title | D1: Priority | E1: Preconditions | F1: Steps | G1: Expected Result | H1: Status | I1: Test Type
A2: Functional | B2: TC-Wallet-01 | C2: Successful Callback – TID Activity | D2: High | E2: Valid accepted callback | F2: 1. Submit successful callback 2. Open merchant TID view 3. Check wallet | G2: Transaction appears under the correct TID with settlement-eligible status; wallet balance remains unchanged; no pending or fee entry. | H2: NA | I2: Functional
A3: Functional | B3: TC-Wallet-02 | C3: Non-Settleable Transactions Visibility | D3: High | E3: Declined/failed callback exists | F3: 1. Submit declined/failed transaction 2. Open TID view 3. Check money totals | G3: Transaction remains visible under the TID but is excluded from all money-looking totals. | H3: NA | I3: Negative
A4: UX/Wording | B4: TC-Wallet-03 | C4: Merchant-Facing Wording & TID Activity | D4: Medium | E4: Per-device (TID) activity view accessible to the merchant | F4: 1. Open per-device view 2. Compare displayed transaction values with wallet balance 3. Review exact copy/labels | G4: TID activity is clearly presented as recorded sales, never as spendable/pending funds. Labels unambiguously describe activity (e.g., "Recorded Sales"). | H4: NA | I4: Usability
A5: Functional | B5: TC-Wallet-04 | C5: Settlement Group Creates One Pending Cash-In | D5: High | E5: EMI-5989 successfully creates a settlement group | F5: 1. Complete grouping 2. Open merchant wallet | G5: Exactly one pending cash-in is created per settlement group; amount is not spendable. | H5: NA | I5: Edge / Boundary
A6: Functional | B6: TC-Wallet-05 | C6: Multiple Settlement Groups Produce Separate Credits | D6: High | E6: Merchant has transactions in multiple settlement groups | F6: 1. Process three settlement groups 2. Complete clearing | G6: Each settlement group produces exactly one balance movement; 3 distinct credits visible, each traceable to its own device/group. | H6: NA | I6: Integration
A7: Functional | B7: TC-Wallet-06 | C7: Pending Cash-In Excluded From Available Balance | D7: High | E7: Pending cash-in exists | F7: 1. Record Available balance 2. Check wallet after pending creation | G7: Pending amount is excluded from Available/spendable balance. | H7: NA | I7: Functional
A8: Functional | B8: TC-Wallet-07 | C8: Intraday Clearing Moves Group to Available | D8: Critical | E8: Valid pending group, matching intraday statement credit, wallet eligible | F8: 1. Process EMI-5922 clearing using batch_ref 2. Run Gate 3 3. Check group and wallet | G8: Pending → Available; member TID entries → SETTLED; exactly one wallet credit. Gate 3 evaluates current state and passes. | H8: NA | I8: Edge / Boundary
A9: Validation | B9: TC-Wallet-08 | C9: Invalid batch_ref Does Not Trigger Settlement | D9: Critical | E9: Pending group exists | F9: 1. Submit intraday credit with invalid/non-matching batch_ref | G9: Group is not credited or incorrectly settled. | H9: NA | I9: Negative
A10: Compliance | B10: TC-Wallet-09 | C10: Gate 3 Failure – SAMA Cap Breach | D10: Critical | E10: Credit would exceed SAMA balance cap | F10: 1. Process intraday credit 2. Force cap failure | G10: Entire amount goes to COMPLIANCE_HOLD/suspense; no partial credit; neutral notification (no tipping-off). | H10: NA | I10: Security
A11: Compliance | B11: TC-Wallet-10 | C11: Wallet Becomes Ineligible Before Credit | D11: Critical | E11: Wallet eligible during grouping but becomes ineligible before clearing | F11: 1. Create pending group 2. Change wallet eligibility 3. Process clearing | G11: Gate 3 evaluates the current state and holds the amount; proves Gate 3 occurs at credit time, not grouping time. | H11: NA | I11: Compliance
A12: Compliance | B12: TC-Wallet-11 | C12: Gate 3 Check-Service Timeout | D12: Critical | E12: Gate 3 (or its dependency, e.g. SAMA cap service) made unresponsive | F12: 1. Process a valid intraday credit while the Gate 3 check service times out | G12: Fail-safe to COMPLIANCE_HOLD/suspense; never fail-open to Available. | H12: NA | I12: Compliance
... A36: Compliance/UX | B36: TC-Wallet-35 | C36: Finance-Facing Held-Funds / Suspense Position View | D36: Medium | E36: One or more wallets hold amounts in COMPLIANCE_HOLD/suspense | F36: 1. Open the Finance-facing held-funds/suspense view 2. Compare totals against the wallet-level suspense entries 3. Confirm traceability to individual held transactions | G36: Finance can see an accurate, traceable picture of all held/suspense funds; the total agrees with the underlying ledger entries. | H36: NA | I36: Integration

Sheet Wallet Payment at Terminal
A1: Subtopic / Category | B1: TC ID | C1: Title | D1: Priority | E1: Preconditions | F1: Steps | G1: Expected Result | H1: Status | I1: Test Type
A2: Functional | B2: TC-WalletPay-01 | C2: Happy Path - Dynamic QR Approval | D2: High | E2: Customer wallet funded above the sale amount; merchant wallet active and fully compliant; terminal online and linked to the merchant wallet | F2: 1. Merchant enters the amount on the terminal 2. Terminal displays the dynamic QR 3. Customer scans the QR in the MJD Pay app 4. Customer approves with PIN or biometric | G2: Authorization approved inside the 10 s end-to-end budget; customer wallet debited; merchant wallet credited; merchant funds spendable at once; commission priced by the commission engine | H2: Not Tested | I2: Functional
A3: Functional | B3: TC-WalletPay-02 | C3: Customer-Presented Code Fallback Uses the Same Authorization API | D3: High | E3: Customer-presented mode enabled; customer wallet funded | F3: 1. Customer displays their code in the app 2. Merchant scans it at the terminal 3. Trace the request path to the authorization endpoint 4. Customer approves | G3: Payment succeeds through the same single authorization API as the QR flow; no second money path exists; the method is switchable by configuration without touching the money path | H3: Not Tested | I3: Integration
A4: Functional | B4: TC-WalletPay-03 | C4: Terminal Resolves to the Correct Merchant Wallet | D4: Medium | E4: Terminal (TID) linked to a known merchant wallet | F4: 1. Submit an authorization for that terminal 2. Inspect the resolved merchant wallet on the authorization record | G4: Terminal resolves to its linked merchant wallet; the credit lands on that wallet and no other | H4: Not Tested | I4: Functional
A5: Functional | B5: TC-WalletPay-04 | C5: Scanned Reference Resolves to the Correct Customer Wallet | D5: Medium | E5: Customer wallet active and funded | F5: 1. Customer scans the terminal QR 2. Inspect the resolved customer wallet on the authorization record | G5: The scanned reference resolves to the scanning customer's wallet; the debit lands on that wallet and no other | H5: Not Tested | I5: Functional
A6: Functional | B6: TC-WalletPay-05 | C6: Merchant Funds Are Spendable Immediately | D6: High | E6: A wallet payment has just been approved at the terminal | F6: 1. Read the merchant's available (spendable) balance immediately after approval 2. Attempt to spend the credited amount straight away | G6: Credited amount is immediately available and spendable; it is never presented as pending, cleared-later or provisional | H6: Not Tested | I6: Functional
A7: Functional | B7: TC-WalletPay-06 | C7: Commission Priced by the Existing Engine on TXN Type + Platform | D7: High | E7: PoS commission scheme configured per EMI-5921; customer wallet funded | F7: 1. Complete a wallet payment at the terminal 2. Inspect the fee entries and the pricing call that was made | G7: Commission is resolved and priced solely by the existing commission engine on TXN type + Platform; no rate is held or computed inside this story | H7: Not Tested | I7: Functional
A8: Functional | B8: TC-WalletPay-07 | C8: Customer In-App Receipt Content | D8: Medium | E8: A wallet payment has been approved | F8: 1. Open the receipt in the customer app | G8: Receipt shows merchant name, amount, any fee and the transaction reference | H8: Not Tested | I8: Functional
A9: Functional | B9: TC-WalletPay-08 | C9: Merchant Notification and Wallet Activity Entry | D9: Medium | E9: A wallet payment has been approved; merchant push notifications enabled | F9: 1. Observe the merchant app after approval 2. Open the merchant wallet activity list | G9: Merchant receives a push notification and an activity entry for the payment, shown as immediately spendable | H9: Not Tested | I9: Functional
A10: Functional | B10: TC-WalletPay-09 | C10: Wallet View Distinguishes Instant Payment from Card Settlement Credit | D10: Medium | E10: Merchant wallet holds both a terminal wallet payment and a card settlement batch credit | F10: 1. Open the merchant wallet activity view 2. Compare how the two credits are presented | G10: The instant wallet payment is visually and semantically distinct from a card settlement credit that lands days later per batch; the merchant can tell them apart without opening details | H10: Not Tested | I10: Functional
A11: Negative | B11: TC-WalletPay-10 | C11: Insufficient Customer Balance Declines Before Any Prompt | D11: High | E11: Customer wallet balance below the sale amount | F11: 1. Submit an authorization for an amount above the customer's balance 2. Observe the customer app throughout | G11: Synchronous decline returned to the terminal; the customer is never prompted for PIN or biometric; nothing moves; no partial payment and no hold is created | H11: Not Tested | I11: Negative
A12: Negative | B12: TC-WalletPay-11 | C12: Customer Never Approves - 90 Second Timeout | D12: High | E12: Customer wallet funded; all checks pass so the prompt is raised | F12: 1. Submit an authorization 2. Leave the customer prompt untouched past the configured window (default 90 s) | G12: Authorization declines at the timeout; terminal shows declined; all balances unchanged | H12: Not Tested | I12: Negative
... A43: Reversal | B43: TC-WalletPay-42 | C43: Reversal Releases No Pending or Reserved Position, Because None Exists | D43: High | E43: A wallet payment reversed after the 15-minute window | F43: 1. Reverse a payment 2. Inspect what the reversal actually released for each party 3. Query for any pending-credit or reserved position at any point in the payment's life | G43: The reversal restores both parties by unwinding a completed internal movement; no pending credit or reserved position is released because none is ever created on this rail. Any pending or reserve found is a defect (cross-check with TC-WalletPay-34) | H43: Not Tested | I43: Negative

Sheet PoS Refunds
A1: Subtopic / Category | B1: TC ID | C1: Title | D1: Priority | E1: Preconditions | F1: Steps | G1: Expected Result | H1: Status | I1: Test Type
A2: Functional | B2: TC-Refund-01 | C2: Refund Captured Against a Known Settled Original | D2: High | E2: A PURCHASE for the same terminal has been captured and settled; refund endpoint reachable | F2: 1. Submit a REFUND event referencing the settled original 2. Inspect the per-TID ledger, the original record and the merchant wallet balance | G2: Refund written to the terminal's per-TID ledger with full detail and its terminal-reported status; original flagged refunded; merchant wallet balance unchanged | H2: Not Tested | I2: Functional
A3: Functional | B3: TC-Refund-02 | C3: Refund Arrives Through the EMI-5915 Entry Point Only | D3: High | E3: Refund capture available | F3: 1. Trace the transport, authentication, hardening and idempotency handling of a REFUND event 2. Search for any refund-specific ingestion endpoint | G3: The refund uses EMI-5915's single entry point with event_type = REFUND; no separate ingestion path or second code path exists | H3: Not Tested | I3: Integration
A4: Functional | B4: TC-Refund-03 | C4: No Wallet Entry, Pending, Fee or Balance Movement on Capture | D4: High | E4: Merchant wallet with a known balance | F4: 1. Capture a refund for that merchant 2. Query wallet entries, pending positions, fee entries and the balance | G4: No wallet entry, no pending, no fee and no balance movement is created; the ledger entry is the only artefact | H4: Not Tested | I4: Functional
A5: Functional | B5: TC-Refund-04 | C5: settlement_expected Is Derived False at Capture | D5: High | E5: Refund capture available | F5: 1. Capture a refund 2. Read settlement_expected on the stored record | G5: settlement_expected is derived as false at capture time, per EMI-5915 section H | H5: Not Tested | I5: Functional
A6: Functional | B6: TC-Refund-05 | C6: settlement_expected Is Immutable After Capture | D6: Medium | E6: A captured refund with settlement_expected = false | F6: 1. Attempt to update settlement_expected on the stored refund through every available path | G6: The field cannot be changed after capture; attempts are rejected and recorded | H6: Not Tested | I6: Negative
A7: Reconciliation | B7: TC-Refund-06 | C7: Refund Never Enters the E13 Candidate Set | D7: High | E7: A captured refund and a reconciliation run for the same date | F7: 1. Run reconciliation (EMI-5920) for the date 2. Inspect the E13 candidate set and the discrepancy queue | G7: The refund is absent from the E13 candidate set and from the discrepancy queue; it is never reported as money the bank failed to settle | H7: Not Tested | I7: Functional
A8: Reconciliation | B8: TC-Refund-07 | C8: Refund Searched For in the Settlement Report | D8: High | E8: A captured refund and the corresponding ANB settlement report | F8: 1. Search the settlement report for the refund | G8: The refund is absent by ANB's settled-only contract; its absence raises no exception and creates no reconciliation discrepancy | H8: Not Tested | I8: Functional
A9: Validation | B9: TC-Refund-08 | C9: Mandatory Field Validation on Capture | D9: High | E9: Refund capture available | F9: 1. Submit refunds each missing one of rrn, amount, occurred_at, original_provider_txn_id | G9: Each is rejected with a clear validation reason and alarmed; capture rejections are never silent | H9: Not Tested | I9: Negative
A10: Validation | B10: TC-Refund-09 | C10: occurred_at Precision Is Preserved in Full | D10: Medium | E10: Refund carrying a high-precision timestamp | F10: 1. Submit the refund 2. Read occurred_at back from storage and compare with the source | G10: occurred_at is stored at full source precision with no truncation or rounding; amount and rrn likewise match the source exactly | H10: Not Tested | I10: Edge / Boundary
A11: Linkage | B11: TC-Refund-10 | C11: Refund Is Linked to Its Original Sale | D11: High | E11: A captured original PURCHASE | F11: 1. Capture a refund carrying original_provider_txn_id 2. Inspect the linkage on both records | G11: The refund resolves to and is linked with its original sale; the link is navigable from either side | H11: Not Tested | I11: Functional
A12: Linkage | B12: TC-Refund-11 | C12: Linkage Is Enforced at Database Level | D12: High | E12: Direct database access available | F12: 1. Attempt to insert a refund row with an original reference that does not exist, bypassing the application | G12: The database rejects the write; linkage is enforced by constraint, not by application code alone | H12: Not Tested | I12: Functional
... A41: Open Question | B41: TC-Refund-40 | C41: Commission on a Refunded Sale - Blocked on O43 | D41: Medium | E41: A settled sale whose commission has been charged, then refunded | F41: 1. Capture the refund 2. Inspect the original commission and VAT entries | G41: EMI-5918 states refund of MJD Pay commission follows O43 and is not designed. Assert only that the existing commission entries are left untouched and nothing is reversed speculatively. Re-scope this case once O43 is answered | H41: Not Tested | I41: Open Question

Sheet Void & Technical Reversal
A1: Subtopic / Category | B1: TC ID | C1: Title | D1: Priority | E1: Preconditions | F1: Steps | G1: Expected Result | H1: Status | I1: Test Type
A2: Functional | B2: TC-Void-01 | C2: Void transaction before settlement | D2: High | E2: Original sale is AWAITING_SETTLEMENT with merchant, commission, and VAT pending entries | F2: 1. Send a valid same-batch void for the original transaction. 2. Process the void callback. 3. Retrieve transaction and wallet/batch records. | G2: Original transaction status becomes CANCELLED. Merchant pending amount is reversed. Commission pending amount is reversed. VAT pending amount is reversed. No money movement occurs. Transaction is excluded from batch settlement expectations. | H2: NA | I2: Functional
A3: Validation | B3: TC-Void-02 | C3: Verify cancellation uses append-only reversal entries | D3: High | E3: Original transaction is AWAITING_SETTLEMENT | F3: 1. Capture the original pending ledger entries. 2. Process a valid void/reversal. 3. Compare ledger records before and after cancellation. | G3: Original ledger entries remain unchanged. New reversal entries are appended for the merchant, commission, and VAT amounts. No existing ledger entry is updated or deleted. | H3: NA | I3: Negative
A4: Validation | B4: TC-Void-03 | C4: Void/Reversal after settlement | D4: High | E4: Original transaction has already been settled | F4: 1. Send a void or technical reversal for the settled transaction. 2. Process the request. 3. Check for an audit/log record of the rejection. | G4: Request returns 200 with a rejected result. Rejection reason is USE_REFUND. Original settled transaction remains unchanged. No reversal/pending-entry cancellation is created. Rejection is captured in the audit log. | H4: NA | I4: Negative
A5: Validation | B5: TC-Void-04 | C5: Void transaction in an invalid lifecycle state | D5: High | E5: Original transaction is in a state other than AWAITING_SETTLEMENT or CANCELLED — e.g. PENDING_AUTH/INITIATED (not yet booked) or DECLINED | F5: 1. Send a void request against a transaction in each listed state. 2. Process the request. | G5: Void is rejected according to lifecycle rules for that state. No pending balance is incorrectly released. No cancellation entries are created. | H5: NA | I5: Negative
A6: Routing | B6: TC-Void-05 | C6: Reversal received before original (valid reference) | D6: High | E6: No original transaction exists yet when the reversal is received; reference format is valid and will eventually match a real transaction | F6: 1. Send technical reversal with a valid transaction reference. 2. Verify ingestion/parking record. 3. Verify transaction state during the parking period. | G6: Reversal is accepted and parked for up to 48 hours. No wallet/ledger cancellation is performed because the original transaction does not yet exist. No erroneous money movement occurs. | H6: NA | I6: Functional
A7: Validation | B7: TC-Void-06 | C7: Reversal/void with an invalid or malformed transaction reference | D7: High | E7: Reversal/void payload references a transaction ID that is structurally invalid or can never resolve to a real transaction | F7: 1. Send technical reversal/void with a malformed or non-existent reference. 2. Process the request. | G7: Request is rejected at ingestion/validation with an explicit error. It is NOT parked — an invalid reference can never be matched to an original. No parking record, wallet entry, or ledger entry is created. | H7: NA | I7: Negative
A8: Routing | B8: TC-Void-07 | C8: Reversal received before original, then original arrives | D8: Critical | E8: Reversal is parked and still within 48-hour window | F8: 1. Submit technical reversal. 2. Submit the matching original transaction before the parking window expires. 3. Process the parked reversal. | G8: Parked reversal is matched to the original. Original is cancelled according to the pre-settlement cancellation rules. Pending merchant, commission, and VAT amounts are reversed through append-only entries. Transaction is excluded from settlement expectations. | H8: NA | I8: Functional
A9: Routing | B9: TC-Void-08 | C9: Reversal received before original and original never arrives | D9: High | E9: Reversal is parked | F9: 1. Submit technical reversal. 2. Do not submit the original transaction. 3. Advance/process beyond the 48-hour parking window. | G9: Parked reversal is closed as a no-op. No wallet/ledger entry is created. No transaction is created or cancelled. No money movement occurs. Audit entry retained. | H9: NA | I9: Functional
A10: Routing | B10: TC-Void-09 | C10: Parking window boundary — original arrives right at the 48h edge | D10: High | E10: Reversal is parked; test harness/clock can control elapsed time precisely | F10: 1. Submit technical reversal. 2. Submit the original at 47h59m — verify it still matches. 3. Repeat with a fresh reversal; submit the original at 48h01m — verify the window has already closed and it does not match. | G10: Original arriving before the 48h boundary matches and triggers cancellation per AC3. Original arriving after the boundary does not match; the reversal has already closed as no-op and the late original processes as a normal (non-reversed) transaction. | H10: NA | I10: Edge / Boundary
A11: Idempotency | B11: TC-Void-10 | C11: Duplicate void or technical reversal | D11: Critical | E11: Original transaction is AWAITING_SETTLEMENT | F11: 1. Submit a valid void/reversal. 2. Process it successfully. 3. Submit the same void/reversal again using the same idempotency/reference information. | G11: First request cancels the transaction. Second request is handled idempotently. No second cancellation occurs. No duplicate reversal entries are created. Final status remains CANCELLED. | H11: NA | I11: Integration
A12: Functional | B12: TC-Void-11 | C12: Wallet-payment technical reversal | D12: Critical | E12: Wallet payment transaction is in the applicable pre-settlement lifecycle state | F12: 1. Create/process a wallet payment. 2. Trigger a technical reversal. 3. Verify transaction and wallet lifecycle states. | G12: Lifecycle failure release is executed. Merchant/customer/related wallet state returns to the defined starting state per Transaction-Lifecycle-Contract Example E. Reserved/pending amounts are released. No residual financial impact remains. | H12: NA | I12: Negative
... A20: Validation | B20: TC-Void-19 | C20: Partial void / partial-amount reversal request | D20: High | E20: Original sale is AWAITING_SETTLEMENT for full amount X | F20: 1. Send a void/reversal request specifying an amount less than the original transaction total. 2. Process the request. | G20: Behavior is undefined in this ticket's AC/T01–T04. Expected until confirmed: request is rejected outright (full-amount-only same-batch void). No partial cancellation entries are created until behavior is confirmed with the story owner. | H20: NA | I20: Negative

Sheet Recon & Three-Way Match
A1: Subtopic / Category | B1: TC ID | C1: Title | D1: Priority | E1: Preconditions | F1: Steps | G1: Expected Result | H1: Status | I1: Test Type
A2: Functional | B2: TC-Recon-01 | C2: Happy Path – Full Three-Way Match (TR_SLIP) | D2: Critical | E2: Valid closed TR_SLIP; PTS rows exist; ledger records exist; a credit-statement record is present in test data whose reference exactly equals TR_SLIP (per the O19/O22 assumption that the reference survives to the credit unaltered); credit = sum of TOTAL_AMOUNT | F2: 1. Run reconciliation. 2. Compare credit reference with TR_SLIP. 3. Compare credit amount with configured net total. 4. Verify ledger members via composite key. 5. Execute EOD cut-off. | G2: TR_SLIP is matched successfully across all three legs (ledger, PTS, credit). Slip marked Matched & Funded. Included in EMI-5922 handoff at EOD cut-off. Note: per the story's primary risk, this full three-way outcome depends on O19/O22 being confirmed – until ANB answers, this scenario is only provable with an assumed/simulated leg-3 reference; see TC-27 for the two-way-only fallback. | H2: NA | I2: Functional
A3: Functional | B3: TC-Recon-02 | C3: Net Expected Total Calculation & Gross-to-Net Bridge | D3: Critical | E3: Sample slip per ANB spec (EMI-5920 data sample): TR_SLIP=78759970, TERMINAL_ID=1653490501111111, LOCALDATE=05/06/2026, row1 AMOUNT=100.00/TR_COM=-0.40/TR_VAT=-0.21/TR_FEE=1.00... i.e. Gross=350.00, ANB deductions=4.14, TOTAL_AMOUNT sum=345.86; configured basis = Net (assumed, O23) | F3: 1. Ingest slip. 2. Run reconciliation. 3. Inspect calculated totals and safeguarding report. | G3: Expected credit = 345.86. Gross, ANB deductions (TR_COM, TR_VAT, TR_FEE), and net are stored independently. Gross − ANB deductions = Net to the halalah. No MJD Pay commission is included. | H3: NA | I3: Functional
A4: Functional | B4: TC-Recon-03 | C4: Member Resolution Using Composite Key | D4: High | E4: Matching PTS row and ledger record have identical TERMINAL_ID, TR_ARF, LOCALDATE | F4: 1. Run reconciliation. 2. Verify member resolution. 3. Across a batch, measure the auto-match rate. | G4: Transaction resolves automatically using the composite key (TERMINAL_ID + TR_ARF + LOCALDATE). No merchant-level decomposition or amount-based fallback is used. Auto-match rate across the batch is ≥ 99.5% (acceptance-criteria target). | H4: NA | I4: Functional
A5: Validation | B5: TC-Recon-04 | C5: Composite Key Mismatch | D5: High | E5: One component of the composite key differs between PTS and ledger | F5: 1. Change TERMINAL_ID, TR_ARF, or LOCALDATE in ledger test data. 2. Run reconciliation. | G5: Transaction is not incorrectly matched. Mismatch is reported. No fuzzy/amount-based fallback occurs. | H5: NA | I5: Negative
A6: Exception | B6: TC-Recon-05 | C6: Ledger Entry Missing From PTS – E13 | D6: Critical | E6: Ledger contains a transaction that does not exist in any eligible PTS slip | F6: 1. Run reconciliation. 2. Keep entry unresolved. 3. Advance three working days. | G6: Entry classified as E13. Remains pending initially. After 3 working days becomes DISPUTED. Unrelated transactions continue normally. E13 rate is fed into the integrity trend (see TC-22/TC-31). | H6: NA | I6: Negative
A7: Exception | B7: TC-Recon-06 | C7: PTS Row Unresolved Against Ledger (Cross-Party Integrity Signal) | D7: High | E7: PTS contains a valid row for which no ledger/BT transaction exists | F7: 1. Run member resolution. 2. Review reconciliation result. | G7: PTS row cannot be resolved to ledger via the composite key. Mismatch recorded with evidence; other rows continue; no amount-based matching attempted. Per EMI-5920 Section G, this is a cross-party integrity signal (BT layer vs PTS) rather than one of the defined match-level exception codes (E13/E15/E16/E18/E19) – the corresponding stale-entry classification is owned by EMI-5991, not this story. | H7: NA | I7: Functional
A8: Exception | B8: TC-Recon-07 | C8: Transaction Amount Mismatch Inside Slip – E15 | D8: Critical | E8: TR_SLIP matches, but one PTS transaction amount differs from ledger | F8: 1. Resolve transaction by composite key. 2. Compare transaction amounts. 3. Run settlement generation. | G8: E15 created for the affected row. Affected row becomes DISPUTED/excluded. Other valid rows in the same slip continue. TR_SLIP match remains valid. | H8: NA | I8: Functional
A9: Exception | B9: TC-Recon-08 | C9: Individual Credit Amount Mismatch – E16 | D9: Critical | E9: Credit reference exactly matches TR_SLIP, but credit differs from expected configured total | F9: 1. Run reconciliation for multiple slips (one with mismatch). 2. Compare credit with expected total. 3. Review settlement candidates. | G9: E16 created. Affected slip is Held. No settlement instruction generated. Other matched/funded slips remain eligible. No amount-based rematching. | H9: NA | I9: Functional
A10: Exception | B10: TC-Recon-09 | C10: Systemic Gross-vs-Net Mismatch – O23 Signature | D10: Critical | E10: Configured basis = Net; credit = sum of AMOUNT instead of TOTAL_AMOUNT, across multiple slips | F10: 1. Process multiple slips where credit equals gross total. 2. Run reconciliation. 3. Review exception reporting. | G10: System identifies common O23 basis-mismatch signature (every failing slip off by exactly the ANB deduction amount). Reported as one systemic finding rather than individual E16 noise, per Section G's explicit instruction to recognize this on day one. | H10: NA | I10: Edge / Boundary
A11: Exception | B11: TC-Recon-10 | C11: Unmatched Credit & Reference Ambiguity – E18 | D11: Critical | E11: Credit reference does not exist in any eligible TR_SLIP (test truncated, prefixed/suffixed, case difference, whitespace) | F11: 1. Process credits with various reference mismatches. 2. Run reconciliation. | G11: E18 created for all variations. Credit is parked. No partial, fuzzy, case-insensitive, or amount-based matching attempted. O19 raised as a live defect/integration risk (per Testing Scenario T13). | H11: NA | I11: Functional
A12: Exception | B12: TC-Recon-11 | C12: Missing Funding – E19 | D12: Critical | E12: Valid closed TR_SLIP exists but no corresponding credit arrives by EOD | F12: 1. Run reconciliation. 2. Reach EOD cut-off. 3. Review slip status. | G12: E19 created. Slip marked Unfunded. Alarm/report generated. No EMI-5922 instruction created. A sustained rise in E19 is escalated to Finance (funding/aggregator problem), not to the merchant. | H12: NA | I12: Negative
... A32: Ops/Reporting | B32: TC-Recon-31 | C32: Recon Dashboard Metrics Completeness | D32: High | E32: Reconciliation has run with a mix of matched, held, exception, and unfunded slips | F32: 1. Open the recon dashboard. 2. Verify each required metric is present and correctly computed. | G32: Dashboard shows: match rate (including the ≥99.5% auto-match target), exceptions by class (E13/E15/E16/E18/E19) with aging, funded vs unfunded value, the safeguarding line, the gross-to-net bridge, and the E13/E19 trend view. | H32: NA | I32: Reporting

Sheet PoS Commission Config
A1: Subtopic / Category | B1: TC ID | C1: Title | D1: Priority | E1: Preconditions | F1: Steps | G1: Expected Result | H1: Status | I1: Test Type
A2: Configuration | B2: TC-Commission-01 | C2: PoS Is Registered as a Platform Value | D2: High | E2: Access to the commission engine reference data | F2: 1. Open the Platform reference values in the commission engine 2. Confirm PoS is present alongside Web and Mobile | G2: PoS exists as a Platform value alongside the existing Web and Mobile values | H2: Not Tested | I2: Configuration
A3: Functional | B3: TC-Commission-02 | C3: Engine Resolves PoS Pricing on TXN Type + Platform | D3: High | E3: PoS scheme configured; an aggregated cash-in with Platform = PoS | F3: 1. Trigger pricing for the aggregated cash-in 2. Trace the resolution the engine performs | G3: Pricing resolves on TXN type + Platform exactly as for every other platform; no new resolution logic is introduced | H3: Not Tested | I3: Integration
A4: Functional | B4: TC-Commission-03 | C4: PoS Settlement Cash-In Is Distinguished From a Wallet Top-Up | D4: High | E4: A PoS settlement cash-in and an ordinary wallet top-up, both standard CASH IN | F4: 1. Price both 2. Compare the schemes resolved and the fees charged | G4: The PoS settlement cash-in is priced by the PoS scheme and the top-up by its own; the Platform value is what separates them; a PoS settlement is never priced as a generic top-up | H4: Not Tested | I4: Functional
A5: Functional | B5: TC-Commission-04 | C5: The Priced Object Is the Aggregated Cash-In per Settlement Batch | D5: High | E5: A settlement batch created in EMI-5989 with Platform = PoS | F5: 1. Inspect the object passed to the commission engine at pricing time | G5: The priced object is the aggregated cash-in for the batch, carrying Platform = PoS; no individual card transaction is passed to the engine | H5: Not Tested | I5: Functional
A6: Functional | B6: TC-Commission-05 | C6: Commission Is Charged Once on the Batch Total | D6: High | E6: A settlement batch containing 40 member sales | F6: 1. Run the batch through ACH preparation 2. Count the commission and VAT entries produced and check the base amount | G6: Commission is charged exactly once, on the batch aggregate net; it is never charged 40 times or per member sale | H6: Not Tested | I6: Edge / Boundary
A7: Functional | B7: TC-Commission-06 | C7: Commission Base Is the Net That Arrived, Not Gross | D7: High | E7: A settlement batch whose Net Settlement Amount is already net of ANB interchange, scheme fee and ANB VAT | F7: 1. Price the batch 2. Compare the commission base with the Net Settlement Amount and with the gross | G7: The base is the net amount that arrived; ANB's interchange, scheme fee, VAT and other charges are never recalculated, never added back and never priced on gross | H7: Not Tested | I7: Functional
A8: Functional | B8: TC-Commission-07 | C8: VAT Applied by the Existing Dual-Commission Machinery | D8: Medium | E8: PoS scheme configured with VAT treatment | F8: 1. Price a batch and inspect the VAT entry | G8: VAT is applied at the prevailing rate by the engine's existing dual-commission and VAT machinery; no VAT logic is introduced by this story | H8: Not Tested | I8: Functional
A9: Functional | B9: TC-Commission-08 | C9: Merchant-Specific Scheme Wins Over the Default | D9: High | E9: A default PoS scheme and a merchant-specific PoS scheme for the same TXN type | F9: 1. Price a batch for that merchant | G9: The merchant-specific scheme is applied; most specific wins under the engine's existing precedence | H9: Not Tested | I9: Functional
A10: Functional | B10: TC-Commission-09 | C10: Group Scheme Wins Over the Default When No Merchant Scheme Exists | D10: Medium | E10: A default and a group PoS scheme; merchant belongs to the group and has no merchant-level scheme | F10: 1. Price a batch for that merchant | G10: The group scheme is applied, ahead of the default and behind any merchant-level scheme | H10: Not Tested | I10: Functional
A11: Functional | B11: TC-Commission-10 | C11: Scheme Key Follows Merchant | Group | Default x Platform x TXN Type | D11: Medium | E11: Schemes configured at all three levels | F11: 1. Price batches for a merchant with each combination present and absent in turn | G11: Resolution follows the documented precedence in every combination; the most specific configured scheme always wins | H11: Not Tested | I11: Functional
A12: Functional | B12: TC-Commission-11 | C12: Merchant With No PoS Scheme Is Credited the Full Batch Net | D12: High | E12: Merchant with no PoS scheme at merchant, group or default level | F12: 1. Run a settlement batch for that merchant through ACH preparation 2. Inspect the credit and the fee entries | G12: The merchant is credited the full batch net with no fee entries; this is a normal outcome and not an error, and nothing is alarmed | H12: Not Tested | I12: Functional
... A32: Open Question | B32: TC-Commission-31 | C32: Per-Scheme Refund Fee Policy - Blocked on O43 | D32: Medium | E32: A scheme carrying any refund fee-policy setting | F32: 1. Inspect whether a refund fee-policy flag exists on the PoS scheme 2. Capture a refund against a priced sale | G32: EMI-5921 places commission refund and claw-back out of scope pending O43. Assert that no refund-driven fee reversal occurs today. Re-scope once O43 is answered and EMI-5918's debit path is designed | H32: Not Tested | I32: Open Question

Sheet ACH & VIBAN per TID
A1: Subtopic / Category | B1: TC ID | C1: Title | D1: Priority | E1: Preconditions | F1: Steps | G1: Expected Result | H1: Status | I1: Test Type
A2: Functional | B2: TC-ACH-01 | C2: Matched Aggregate – ACH Item Generation | D2: Critical | E2: Aggregate is matched and funded by Reconciliation; merchant is eligible | F2: 1. Handoff matched aggregate to settlement. 2. Build settlement batch. 3. Inspect generated ACH item. | G2: One settlement item is created per TID group. item_ref, batch_ref, TID, wallet, VIBAN and aggregate net amount are persisted. Item is AWAITING_APPROVAL. | H2: NA | I2: Functional
A3: Functional | B3: TC-ACH-02 | C3: One Merchant With Multiple TIDs | D3: Critical | E3: One merchant has 3 TIDs with separate matched aggregates | F3: 1. Process the three aggregates. 2. Build settlement batch. | G3: Exactly 3 ACH items / 3 transfers are created. Each item has its own batch_ref and amount. Items are not aggregated across TIDs. | H3: NA | I3: Edge / Boundary
A4: Functional | B4: TC-ACH-03 | C4: Idempotent ACH Generation | D4: Critical | E4: Valid matched aggregate already generated an ACH item | F4: 1. Run generation. 2. Re-run reconciliation/batch build. 3. Re-run catch-up/rebuild. | G4: Only one ACH item/transfer exists for the batch_ref. No duplicate payment or settlement item is created. | H4: NA | I4: Integration
A5: Functional | B5: TC-ACH-04 | C5: Gate 2 – Merchant Eligibility and Sanctions Check | D5: Critical | E5: Aggregate matched; merchant status changes after initial screening | F5: 1. Change merchant eligibility before batch release. 2. Run Gate 2. 3. Repeat with a newly matched sanctions hit. | G5: Failed eligibility or sanctions screening excludes the item from release. Funds remain in the omnibus. No ACH instruction is released. | H5: NA | I5: Functional
A6: Functional | B6: TC-ACH-05 | C6: ACH Reference Propagation | D6: Critical | E6: Valid settlement item with known batch_ref | F6: 1. Generate ACH instruction. 2. Inspect ACH request. | G6: batch_ref is written to the ACH notes/remittance field unchanged. The same reference is available for subsequent clearing. | H6: NA | I6: Functional
A7: Functional | B7: TC-ACH-06 | C7: Maker-Checker Approval | D7: Critical | E7: Default automatic mode is disabled | F7: 1. Generate valid ACH items. 2. Review approval status. 3. Finance approves. 4. Release transfer. | G7: ACH item cannot be released before Finance approval. Approval and release are audit logged with actor and batch_ref. | H7: NA | I7: Functional
A8: Functional | B8: TC-ACH-07 | C8: Automatic Release Mode | D8: High | E8: Automatic mode explicitly enabled and item meets configured threshold | F8: 1. Enable auto-release configuration. 2. Generate eligible item. 3. Process release. | G8: Item is released automatically without manual approval. Auto-release decision is audit logged. Items outside threshold remain subject to control. | H8: NA | I8: Functional
A9: Functional | B9: TC-ACH-08 | C9: Intraday Credit Clears Pending Cash-In | D9: Critical | E9: ACH executed; intraday statement contains credit with matching batch_ref; credit amount equals pending amount | F9: 1. Process intraday statement. 2. Find credit using batch_ref. 3. Check pending cash-in. | G9: Existing aggregated CASH IN changes from PENDING → SUCCESSFUL. Member per-TID entries settle accordingly. No new cash-in is created. | H9: NA | I9: Functional
A10: Functional | B10: TC-ACH-09 | C10: Intraday Credit Amount Mismatch | D10: Critical | E10: Credit reference matches batch_ref, but credited amount differs from pending amount | F10: 1. Process intraday statement. 2. Match reference. 3. Compare amounts. | G10: Pending cash-in remains unchanged/PENDING. Nothing is partially cleared. Item moves to discrepancy queue. No additional cash-in is booked. | H10: NA | I10: Functional
A11: Functional | B11: TC-ACH-10 | C11: Credit Without Valid Reference | D11: Critical | E11: Intraday credit has no recognizable batch_ref or contains a malformed/truncated reference | F11: 1. Process statement credit. 2. Run clearing job. | G11: Credit is parked for Ops. No matching by amount/date is attempted. No pending cash-in is cleared. Reference integrity issue is raised. | H11: NA | I11: Functional
A12: Functional | B12: TC-ACH-11 | C12: Unknown batch_ref | D12: High | E12: Credit contains a validly formatted but unknown batch_ref | F12: 1. Process credit. 2. Run clearing job. | G12: Credit is parked as an exception. No cash-in is booked. No pending transaction is cleared. No amount-based fallback occurs. | H12: NA | I12: Negative
... A96: ACH Cut-off | B96: TC-ACH-95 | C96: ACH cut-off is enforced and items beyond the cut-off are held for the next processing window | D96: High | E96: ACH cut-off time is configured. A settlement batch becomes eligible after the configured cut-off. | F96: 1. Create/prepare a settlement after the cut-off time. 2. Run ACH generation/release. 3. Review the batch status and ACH instruction. 4. Run the next processing window. | G96: The item is not released in the closed processing window. It remains pending/held and becomes eligible for the next permitted processing window. | H96: Not Tested | I96: Functional

Sheet PoS Compliance Gates
A1: Subtopic / Category | B1: TC ID | C1: Title | D1: Priority | E1: Preconditions | F1: Steps | G1: Expected Result | H1: Status | I1: Test Type
A2: Compliance | B2: TC-Compliance-01 | C2: Gate 1 Hold on AML-Reviewed Wallet | D2: High | E2: Wallet is flagged under AML review at the moment a PoS callback arrives | F2: 1. Submit a valid PoS callback for the flagged wallet 2. Run Gate 1 at booking 3. Inspect ledger and case management | G2: Transaction is COMPLIANCE_HOLD with the failing check code recorded; zero wallet entries (not even Pending); device-journal HOLD entry written; a compliance case is opened. | H2: NA | I2: Edge / Boundary
A3: Compliance | B3: TC-Compliance-02 | C3: Cleared Case Re-Enters Next Batch via Gate 2 | D3: High | E3: A previously held transaction's compliance case has been cleared by Compliance/MLRO | F3: 1. Clear the case 2. Allow the transaction to reach the next batch build 3. Observe Gate 2 evaluation and settlement | G3: The transaction re-enters the next batch via Gate 2 and settles normally if it passes. | H3: NA | I3: Compliance
A4: Compliance | B4: TC-Compliance-03 | C4: Gate 2 Excludes Item Blocked Between Booking and Batch Build | D4: High | E4: Wallet is eligible at booking (Gate 1 pass) but becomes blocked before batch build | F4: 1. Book the transaction (Gate 1 pass) 2. Block the wallet 3. Run Gate 2 at batch build | G4: Gate 2 excludes the item from the ACH batch; funds stay in the PoS omnibus; case raised. | H4: NA | I4: Compliance
A5: Compliance | B5: TC-Compliance-04 | C5: Gate 3 — Credit Would Breach SAMA Balance Cap | D5: Critical | E5: Crediting this amount at this instant would breach the wallet's SAMA balance cap | F5: 1. Run Gate 3 immediately before Pending → Available 2. Attempt the credit | G5: Gate 3 → HOLD + ledger suspense position; no partial credit; merchant is notified with neutral, tier/cash-out wording only (no tipping-off). | H5: NA | I5: Security
A6: Compliance | B6: TC-Compliance-05 | C6: Sanctions List Update Between Recon and Release | D6: Critical | E6: A sanctions list update lands after EMI-5920 matching but before EMI-5922 release | F6: 1. Match and fund the aggregate 2. Update the sanctions list with a hit against the merchant 3. Run the pre-release re-screen | G6: The re-screen catches the new hit and the item is excluded before release. | H6: NA | I6: Compliance
A7: UX | B7: TC-Compliance-06 | C7: Neutral State Across All Merchant-Facing Surfaces During Hold | D7: High | E7: A transaction/group is currently COMPLIANCE_HOLD or in suspense | F7: 1. Inspect the merchant app, portal, notifications, statements and support views for the held item 2. Compare wording/state across every surface | G7: Every merchant-facing surface shows a neutral 'processing' state only; no review indicator, hold label, or compliance signal leaks anywhere in the payload. | H7: NA | I7: Security
A8: Reporting | B8: TC-Compliance-07 | C8: Held-Funds Daily Report Reconciles Exactly | D8: High | E8: A day's activity includes credited, held (Gate 1 and Gate 3) and in-transit amounts | F8: 1. Generate the daily held-funds report 2. Compare gross received against credited + held + in-transit, to the halalah | G8: Gross received = credited + held + in-transit exactly; this is the safeguarding evidence figure. | H8: NA | I8: Edge / Boundary
A9: Compliance | B9: TC-Compliance-08 | C9: Hold Aging Past SLA Escalates to MLRO | D9: Medium | E9: A held case has been open beyond the proposed 5-business-day SLA without a decision | F9: 1. Let a held case age past the SLA 2. Observe the aging job | G9: RF-10 escalation is raised to the MLRO once the SLA is breached. | H9: NA | I9: Compliance
A10: Functional | B10: TC-Compliance-09 | C10: Gate 1 Fail Writes Zero Wallet Entries, Not Even Pending | D10: High | E10: Wallet fails a Gate 1 check (status/AML/sanctions/SAMA/fraud) | F10: 1. Trigger a Gate 1 fail on booking 2. Query all wallet ledger tables for the transaction | G10: No wallet entries exist at all for the transaction — not Pending, not any other bucket — confirming the AC's stricter-than-usual 'no wallet entries at all (not even Pending)' requirement. | H10: NA | I10: Edge / Boundary
A11: Reliability | B11: TC-Compliance-10 | C11: Gate 1 Check-Service Timeout Fails Safe to HOLD | D11: High | E11: The Gate 1 check service (wallet status/AML/sanctions/SAMA/fraud) is made unresponsive | F11: 1. Submit a valid callback while the Gate 1 service times out | G11: Fail-safe to HOLD; the transaction is never fail-open to booking. | H11: NA | I11: Negative
A12: Reliability | B12: TC-Compliance-11 | C12: Gate 3 Check-Service Timeout Defers, Retries and Alarms | D12: High | E12: The Gate 3 check service (SAMA balance-cap headroom) is made unresponsive at the instant of crediting | F12: 1. Attempt a credit while the Gate 3 service times out | G12: Credit is deferred and retried (not immediately failed to HOLD as Gate 1 is); the timeout is alarmed for Ops visibility. | H12: NA | I12: Functional
