Workbook

Sheet Overview
A1: Category | B1: Details
A2: Document Name | B2: EMI Manual Test Cases — B2B — By Feature
A3: Epic / Story Ref | B3: Full EMI manual suite: project docs + this audit + AIO (Jira)
A4: Release Number | B4: All releases to V 6.6.0 / Sprint 74
A5: Environment | B5: UAT
A6: Testing Period | B6: Sprint Test Execution Cycle
A9: EMI Manual Test Cases — B2B — Results by Feature
A11: Feature | B11: Passed | C11: Failed | D11: Partially Passed | E11: Not Tested | F11: Not Implemented | G11: Total Checks | H11: Pass Rate %
A12: Technical Updates | B12: =COUNTIF('Technical Updates'!$I:$I,"Passed") -> 0 | C12: =COUNTIF('Technical Updates'!$I:$I,"Failed") -> 0 | D12: =COUNTIF('Technical Updates'!$I:$I,"Partially Passed") -> 0 | E12: =COUNTIF('Technical Updates'!$I:$I,"Not Tested") -> 1247 | F12: =COUNTIF('Technical Updates'!$I:$I,"Not Implemented") -> 0 | G12: =SUM(B12:F12) -> 1247 | H12: =IF(G12>0,B12/G12,0) -> 0
A13: Deep Payment | B13: =COUNTIF('Deep Payment'!$I:$I,"Passed") -> 0 | C13: =COUNTIF('Deep Payment'!$I:$I,"Failed") -> 0 | D13: =COUNTIF('Deep Payment'!$I:$I,"Partially Passed") -> 0 | E13: =COUNTIF('Deep Payment'!$I:$I,"Not Tested") -> 701 | F13: =COUNTIF('Deep Payment'!$I:$I,"Not Implemented") -> 0 | G13: =SUM(B13:F13) -> 701 | H13: =IF(G13>0,B13/G13,0) -> 0
A14: PoS Transactions | B14: =COUNTIF('PoS Transactions'!$I:$I,"Passed") -> 0 | C14: =COUNTIF('PoS Transactions'!$I:$I,"Failed") -> 0 | D14: =COUNTIF('PoS Transactions'!$I:$I,"Partially Passed") -> 0 | E14: =COUNTIF('PoS Transactions'!$I:$I,"Not Tested") -> 420 | F14: =COUNTIF('PoS Transactions'!$I:$I,"Not Implemented") -> 0 | G14: =SUM(B14:F14) -> 420 | H14: =IF(G14>0,B14/G14,0) -> 0
A15: Setup & Admin | B15: =COUNTIF('Setup & Admin'!$I:$I,"Passed") -> 0 | C15: =COUNTIF('Setup & Admin'!$I:$I,"Failed") -> 0 | D15: =COUNTIF('Setup & Admin'!$I:$I,"Partially Passed") -> 0 | E15: =COUNTIF('Setup & Admin'!$I:$I,"Not Tested") -> 567 | F15: =COUNTIF('Setup & Admin'!$I:$I,"Not Implemented") -> 0 | G15: =SUM(B15:F15) -> 567 | H15: =IF(G15>0,B15/G15,0) -> 0
A16: Transaction Operations | B16: =COUNTIF('Transaction Operations'!$I:$I,"Passed") -> 0 | C16: =COUNTIF('Transaction Operations'!$I:$I,"Failed") -> 0 | D16: =COUNTIF('Transaction Operations'!$I:$I,"Partially Passed") -> 0 | E16: =COUNTIF('Transaction Operations'!$I:$I,"Not Tested") -> 516 | F16: =COUNTIF('Transaction Operations'!$I:$I,"Not Implemented") -> 0 | G16: =SUM(B16:F16) -> 516 | H16: =IF(G16>0,B16/G16,0) -> 0
A17: Registration | B17: =COUNTIF(Registration!$I:$I,"Passed") -> 0 | C17: =COUNTIF(Registration!$I:$I,"Failed") -> 0 | D17: =COUNTIF(Registration!$I:$I,"Partially Passed") -> 0 | E17: =COUNTIF(Registration!$I:$I,"Not Tested") -> 494 | F17: =COUNTIF(Registration!$I:$I,"Not Implemented") -> 0 | G17: =SUM(B17:F17) -> 494 | H17: =IF(G17>0,B17/G17,0) -> 0
A18: Balances & Wallet Consistency | B18: =COUNTIF('Balances & Wallet Consistency'!$I:$I,"Passed") -> 0 | C18: =COUNTIF('Balances & Wallet Consistency'!$I:$I,"Failed") -> 0 | D18: =COUNTIF('Balances & Wallet Consistency'!$I:$I,"Partially Passed") -> 0 | E18: =COUNTIF('Balances & Wallet Consistency'!$I:$I,"Not Tested") -> 330 | F18: =COUNTIF('Balances & Wallet Consistency'!$I:$I,"Not Implemented") -> 0 | G18: =SUM(B18:F18) -> 330 | H18: =IF(G18>0,B18/G18,0) -> 0
A19: Products | B19: =COUNTIF(Products!$I:$I,"Passed") -> 0 | C19: =COUNTIF(Products!$I:$I,"Failed") -> 0 | D19: =COUNTIF(Products!$I:$I,"Partially Passed") -> 0 | E19: =COUNTIF(Products!$I:$I,"Not Tested") -> 300 | F19: =COUNTIF(Products!$I:$I,"Not Implemented") -> 0 | G19: =SUM(B19:F19) -> 300 | H19: =IF(G19>0,B19/G19,0) -> 0
A20: Integrations | B20: =COUNTIF(Integrations!$I:$I,"Passed") -> 0 | C20: =COUNTIF(Integrations!$I:$I,"Failed") -> 0 | D20: =COUNTIF(Integrations!$I:$I,"Partially Passed") -> 0 | E20: =COUNTIF(Integrations!$I:$I,"Not Tested") -> 264 | F20: =COUNTIF(Integrations!$I:$I,"Not Implemented") -> 0 | G20: =SUM(B20:F20) -> 264 | H20: =IF(G20>0,B20/G20,0) -> 0
A21: Login | B21: =COUNTIF(Login!$I:$I,"Passed") -> 0 | C21: =COUNTIF(Login!$I:$I,"Failed") -> 0 | D21: =COUNTIF(Login!$I:$I,"Partially Passed") -> 0 | E21: =COUNTIF(Login!$I:$I,"Not Tested") -> 253 | F21: =COUNTIF(Login!$I:$I,"Not Implemented") -> 0 | G21: =SUM(B21:F21) -> 253 | H21: =IF(G21>0,B21/G21,0) -> 0
A22: RMS | B22: =COUNTIF(RMS!$I:$I,"Passed") -> 0 | C22: =COUNTIF(RMS!$I:$I,"Failed") -> 0 | D22: =COUNTIF(RMS!$I:$I,"Partially Passed") -> 0 | E22: =COUNTIF(RMS!$I:$I,"Not Tested") -> 240 | F22: =COUNTIF(RMS!$I:$I,"Not Implemented") -> 0 | G22: =SUM(B22:F22) -> 240 | H22: =IF(G22>0,B22/G22,0) -> 0
A23: Multi-Omnibus | B23: =COUNTIF('Multi-Omnibus'!$I:$I,"Passed") -> 0 | C23: =COUNTIF('Multi-Omnibus'!$I:$I,"Failed") -> 0 | D23: =COUNTIF('Multi-Omnibus'!$I:$I,"Partially Passed") -> 0 | E23: =COUNTIF('Multi-Omnibus'!$I:$I,"Not Tested") -> 196 | F23: =COUNTIF('Multi-Omnibus'!$I:$I,"Not Implemented") -> 0 | G23: =SUM(B23:F23) -> 196 | H23: =IF(G23>0,B23/G23,0) -> 0
A24: Roles & Permissions | B24: =COUNTIF('Roles & Permissions'!$I:$I,"Passed") -> 0 | C24: =COUNTIF('Roles & Permissions'!$I:$I,"Failed") -> 0 | D24: =COUNTIF('Roles & Permissions'!$I:$I,"Partially Passed") -> 0 | E24: =COUNTIF('Roles & Permissions'!$I:$I,"Not Tested") -> 193 | F24: =COUNTIF('Roles & Permissions'!$I:$I,"Not Implemented") -> 0 | G24: =SUM(B24:F24) -> 193 | H24: =IF(G24>0,B24/G24,0) -> 0
A25: Dashboard & Wallets | B25: =COUNTIF('Dashboard & Wallets'!$I:$I,"Passed") -> 0 | C25: =COUNTIF('Dashboard & Wallets'!$I:$I,"Failed") -> 0 | D25: =COUNTIF('Dashboard & Wallets'!$I:$I,"Partially Passed") -> 0 | E25: =COUNTIF('Dashboard & Wallets'!$I:$I,"Not Tested") -> 189 | F25: =COUNTIF('Dashboard & Wallets'!$I:$I,"Not Implemented") -> 0 | G25: =SUM(B25:F25) -> 189 | H25: =IF(G25>0,B25/G25,0) -> 0
A26: Sub-Wallets | B26: =COUNTIF('Sub-Wallets'!$I:$I,"Passed") -> 0 | C26: =COUNTIF('Sub-Wallets'!$I:$I,"Failed") -> 0 | D26: =COUNTIF('Sub-Wallets'!$I:$I,"Partially Passed") -> 0 | E26: =COUNTIF('Sub-Wallets'!$I:$I,"Not Tested") -> 182 | F26: =COUNTIF('Sub-Wallets'!$I:$I,"Not Implemented") -> 0 | G26: =SUM(B26:F26) -> 182 | H26: =IF(G26>0,B26/G26,0) -> 0
A27: Top Up & Cash In | B27: =COUNTIF('Top Up & Cash In'!$I:$I,"Passed") -> 0 | C27: =COUNTIF('Top Up & Cash In'!$I:$I,"Failed") -> 0 | D27: =COUNTIF('Top Up & Cash In'!$I:$I,"Partially Passed") -> 0 | E27: =COUNTIF('Top Up & Cash In'!$I:$I,"Not Tested") -> 169 | F27: =COUNTIF('Top Up & Cash In'!$I:$I,"Not Implemented") -> 0 | G27: =SUM(B27:F27) -> 169 | H27: =IF(G27>0,B27/G27,0) -> 0
A28: Adjustments & Reversals | B28: =COUNTIF('Adjustments & Reversals'!$I:$I,"Passed") -> 0 | C28: =COUNTIF('Adjustments & Reversals'!$I:$I,"Failed") -> 0 | D28: =COUNTIF('Adjustments & Reversals'!$I:$I,"Partially Passed") -> 0 | E28: =COUNTIF('Adjustments & Reversals'!$I:$I,"Not Tested") -> 136 | F28: =COUNTIF('Adjustments & Reversals'!$I:$I,"Not Implemented") -> 0 | G28: =SUM(B28:F28) -> 136 | H28: =IF(G28>0,B28/G28,0) -> 0
A29: Reconciliation | B29: =COUNTIF(Reconciliation!$I:$I,"Passed") -> 0 | C29: =COUNTIF(Reconciliation!$I:$I,"Failed") -> 0 | D29: =COUNTIF(Reconciliation!$I:$I,"Partially Passed") -> 0 | E29: =COUNTIF(Reconciliation!$I:$I,"Not Tested") -> 132 | F29: =COUNTIF(Reconciliation!$I:$I,"Not Implemented") -> 0 | G29: =SUM(B29:F29) -> 132 | H29: =IF(G29>0,B29/G29,0) -> 0
A30: Profile & Manage Accounts | B30: =COUNTIF('Profile & Manage Accounts'!$I:$I,"Passed") -> 0 | C30: =COUNTIF('Profile & Manage Accounts'!$I:$I,"Failed") -> 0 | D30: =COUNTIF('Profile & Manage Accounts'!$I:$I,"Partially Passed") -> 0 | E30: =COUNTIF('Profile & Manage Accounts'!$I:$I,"Not Tested") -> 130 | F30: =COUNTIF('Profile & Manage Accounts'!$I:$I,"Not Implemented") -> 0 | G30: =SUM(B30:F30) -> 130 | H30: =IF(G30>0,B30/G30,0) -> 0
A31: Money Request | B31: =COUNTIF('Money Request'!$I:$I,"Passed") -> 0 | C31: =COUNTIF('Money Request'!$I:$I,"Failed") -> 0 | D31: =COUNTIF('Money Request'!$I:$I,"Partially Passed") -> 0 | E31: =COUNTIF('Money Request'!$I:$I,"Not Tested") -> 127 | F31: =COUNTIF('Money Request'!$I:$I,"Not Implemented") -> 0 | G31: =SUM(B31:F31) -> 127 | H31: =IF(G31>0,B31/G31,0) -> 0
A32: Forgot Password | B32: =COUNTIF('Forgot Password'!$I:$I,"Passed") -> 0 | C32: =COUNTIF('Forgot Password'!$I:$I,"Failed") -> 0 | D32: =COUNTIF('Forgot Password'!$I:$I,"Partially Passed") -> 0 | E32: =COUNTIF('Forgot Password'!$I:$I,"Not Tested") -> 115 | F32: =COUNTIF('Forgot Password'!$I:$I,"Not Implemented") -> 0 | G32: =SUM(B32:F32) -> 115 | H32: =IF(G32>0,B32/G32,0) -> 0
A33: Bill Payment | B33: =COUNTIF('Bill Payment'!$I:$I,"Passed") -> 0 | C33: =COUNTIF('Bill Payment'!$I:$I,"Failed") -> 0 | D33: =COUNTIF('Bill Payment'!$I:$I,"Partially Passed") -> 0 | E33: =COUNTIF('Bill Payment'!$I:$I,"Not Tested") -> 111 | F33: =COUNTIF('Bill Payment'!$I:$I,"Not Implemented") -> 0 | G33: =SUM(B33:F33) -> 111 | H33: =IF(G33>0,B33/G33,0) -> 0
A34: Platform & System | B34: =COUNTIF('Platform & System'!$I:$I,"Passed") -> 0 | C34: =COUNTIF('Platform & System'!$I:$I,"Failed") -> 0 | D34: =COUNTIF('Platform & System'!$I:$I,"Partially Passed") -> 0 | E34: =COUNTIF('Platform & System'!$I:$I,"Not Tested") -> 111 | F34: =COUNTIF('Platform & System'!$I:$I,"Not Implemented") -> 0 | G34: =SUM(B34:F34) -> 111 | H34: =IF(G34>0,B34/G34,0) -> 0
A35: Bill Management (Creation) | B35: =COUNTIF('Bill Management (Creation)'!$I:$I,"Passed") -> 0 | C35: =COUNTIF('Bill Management (Creation)'!$I:$I,"Failed") -> 0 | D35: =COUNTIF('Bill Management (Creation)'!$I:$I,"Partially Passed") -> 0 | E35: =COUNTIF('Bill Management (Creation)'!$I:$I,"Not Tested") -> 107 | F35: =COUNTIF('Bill Management (Creation)'!$I:$I,"Not Implemented") -> 0 | G35: =SUM(B35:F35) -> 107 | H35: =IF(G35>0,B35/G35,0) -> 0
A36: Transaction Log | B36: =COUNTIF('Transaction Log'!$I:$I,"Passed") -> 0 | C36: =COUNTIF('Transaction Log'!$I:$I,"Failed") -> 0 | D36: =COUNTIF('Transaction Log'!$I:$I,"Partially Passed") -> 0 | E36: =COUNTIF('Transaction Log'!$I:$I,"Not Tested") -> 96 | F36: =COUNTIF('Transaction Log'!$I:$I,"Not Implemented") -> 0 | G36: =SUM(B36:F36) -> 96 | H36: =IF(G36>0,B36/G36,0) -> 0
A37: KYC - KYB - AML | B37: =COUNTIF('KYC - KYB - AML'!$I:$I,"Passed") -> 0 | C37: =COUNTIF('KYC - KYB - AML'!$I:$I,"Failed") -> 0 | D37: =COUNTIF('KYC - KYB - AML'!$I:$I,"Partially Passed") -> 0 | E37: =COUNTIF('KYC - KYB - AML'!$I:$I,"Not Tested") -> 93 | F37: =COUNTIF('KYC - KYB - AML'!$I:$I,"Not Implemented") -> 0 | G37: =SUM(B37:F37) -> 93 | H37: =IF(G37>0,B37/G37,0) -> 0
A38: QR Payment | B38: =COUNTIF('QR Payment'!$I:$I,"Passed") -> 0 | C38: =COUNTIF('QR Payment'!$I:$I,"Failed") -> 0 | D38: =COUNTIF('QR Payment'!$I:$I,"Partially Passed") -> 0 | E38: =COUNTIF('QR Payment'!$I:$I,"Not Tested") -> 87 | F38: =COUNTIF('QR Payment'!$I:$I,"Not Implemented") -> 0 | G38: =SUM(B38:F38) -> 87 | H38: =IF(G38>0,B38/G38,0) -> 0
A39: Bank Transfer & Cash Out | B39: =COUNTIF('Bank Transfer & Cash Out'!$I:$I,"Passed") -> 0 | C39: =COUNTIF('Bank Transfer & Cash Out'!$I:$I,"Failed") -> 0 | D39: =COUNTIF('Bank Transfer & Cash Out'!$I:$I,"Partially Passed") -> 0 | E39: =COUNTIF('Bank Transfer & Cash Out'!$I:$I,"Not Tested") -> 83 | F39: =COUNTIF('Bank Transfer & Cash Out'!$I:$I,"Not Implemented") -> 0 | G39: =SUM(B39:F39) -> 83 | H39: =IF(G39>0,B39/G39,0) -> 0
A40: JIT | B40: =COUNTIF(JIT!$I:$I,"Passed") -> 0 | C40: =COUNTIF(JIT!$I:$I,"Failed") -> 0 | D40: =COUNTIF(JIT!$I:$I,"Partially Passed") -> 0 | E40: =COUNTIF(JIT!$I:$I,"Not Tested") -> 83 | F40: =COUNTIF(JIT!$I:$I,"Not Implemented") -> 0 | G40: =SUM(B40:F40) -> 83 | H40: =IF(G40>0,B40/G40,0) -> 0
A41: Notifications | B41: =COUNTIF(Notifications!$I:$I,"Passed") -> 0 | C41: =COUNTIF(Notifications!$I:$I,"Failed") -> 0 | D41: =COUNTIF(Notifications!$I:$I,"Partially Passed") -> 0 | E41: =COUNTIF(Notifications!$I:$I,"Not Tested") -> 77 | F41: =COUNTIF(Notifications!$I:$I,"Not Implemented") -> 0 | G41: =SUM(B41:F41) -> 77 | H41: =IF(G41>0,B41/G41,0) -> 0
A42: Wallet Configuration | B42: =COUNTIF('Wallet Configuration'!$I:$I,"Passed") -> 0 | C42: =COUNTIF('Wallet Configuration'!$I:$I,"Failed") -> 0 | D42: =COUNTIF('Wallet Configuration'!$I:$I,"Partially Passed") -> 0 | E42: =COUNTIF('Wallet Configuration'!$I:$I,"Not Tested") -> 77 | F42: =COUNTIF('Wallet Configuration'!$I:$I,"Not Implemented") -> 0 | G42: =SUM(B42:F42) -> 77 | H42: =IF(G42>0,B42/G42,0) -> 0
A43: Reports | B43: =COUNTIF(Reports!$I:$I,"Passed") -> 0 | C43: =COUNTIF(Reports!$I:$I,"Failed") -> 0 | D43: =COUNTIF(Reports!$I:$I,"Partially Passed") -> 0 | E43: =COUNTIF(Reports!$I:$I,"Not Tested") -> 69 | F43: =COUNTIF(Reports!$I:$I,"Not Implemented") -> 0 | G43: =SUM(B43:F43) -> 69 | H43: =IF(G43>0,B43/G43,0) -> 0
...

Sheet Technical Updates
A1: TC ID | B1: Sub-Area | C1: Source ID | D1: Title | E1: Priority | F1: Preconditions | G1: Steps | H1: Expected Result | I1: Status | J1: Test Type | K1: Interface | L1: Source | M1: Jira Ref | N1: Automated | O1: Automated By | P1: Channel
A2: EMI-B2B-6750 | B2: 5.1.0 | C2: EMI-TC-5033 | D2: Checking the VAT checkbox applies VAT to the bill total | E2: Critical | F2: Edit bill form is open. VAT checkbox is unchecked. | G2: Check the VAT checkbox and observe the bill total. | H2: Bill total updates to include the applicable VAT amount. VAT line is shown in the bill summary. Change is reflected immediately without a page reload. | I2: Not Tested | J2: Functional | K2: Web | L2: AIO (Jira) | N2: No | P2: B2B
A3: EMI-B2B-6755 | B3: 5.1.0 | C3: EMI-TC-5038 | D3: Issue Date field is removed from the edit bill form | E3: Critical | F3: Edit bill form is open. | G3: Inspect the edit bill form for the Issue Date field. | H3: Issue Date field is not present in the form. It is fully removed, not disabled. No greyed-out or read-only date input remains. | I3: Not Tested | J3: Functional | K3: Web | L3: AIO (Jira) | M3: EMI-5199 | N3: No | P3: B2B
A4: EMI-B2B-6758 | B4: 5.1.0 | C4: EMI-TC-5041 | D4: VAT checkbox and field removals are applied in the single bill edit view | E4: Critical | F4: A single bill is open in edit mode. | G4: Inspect the single bill edit form for VAT field type and presence of Select Beneficiary and Issue Date. | H4: VAT is a checkbox. Select Beneficiary and Issue Date are absent. All other editable fields are present and functional. | I4: Not Tested | J4: Functional | K4: Web | L4: AIO (Jira) | M4: EMI-5199 | N4: No | P4: B2B
A5: EMI-B2B-6761 | B5: 5.1.0 | C5: EMI-TC-5044 | D5: VAT checkbox and field removals are applied in the detailed bill edit view | E5: Critical | F5: A detailed (multi-line) bill is open in edit mode. | G5: Inspect the detailed bill edit form for VAT field type and presence of Select Beneficiary and Issue Date. | H5: VAT is a checkbox. Select Beneficiary and Issue Date are absent. All line-item editable fields are present and functional. | I5: Not Tested | J5: Functional | K5: Web | L5: AIO (Jira) | M5: EMI-5199 | N5: No | P5: B2B
A6: EMI-B2B-6709 | B6: 5.1.0 | C6: EMI-TC-4640 | D6: SessionManager initialises correctly as a singleton via Koin | E6: High | F6: App is launched. Koin dependency modules are configured with SessionManager provided as singleton. | G6: 1. Launch the application 2. Resolve SessionManager from Koin in two separate places 3. Compare both instances | H6: Both resolved instances are the same object reference (singleton). SessionManager is not recreated on each resolution. | I6: Not Tested | J6: Functional | K6: Web | L6: AIO (Jira) | M6: EMI-5213 | N6: No | P6: B2B
A7: EMI-B2B-6710 | B7: 5.1.0 | C7: EMI-TC-4641 | D7: SessionManager starts session timeout coroutine on user login | E7: High | F7: User is on the login screen. SessionManager is initialised. | G7: 1. Complete user login successfully 2. Observe SessionManager coroutine state | H7: Session timeout coroutine is launched and running after login. Coroutine is scoped correctly and does not run before login. | I7: Not Tested | J7: Functional | K7: Web | L7: AIO (Jira) | M7: EMI-5213 | N7: No | P7: B2B
A8: EMI-B2B-6720 | B8: 5.1.0 | C8: EMI-TC-4651 | D8: Session handling in MainActivity behaves equivalently to former BaseActivity | E8: High | F8: Previous session behaviour documented. App is running with new architecture. | G8: 1. Perform a full user session: login, idle, timeout, re-login 2. Compare behaviour to pre-refactor baseline | H8: Session timeout, logout, and re-authentication behave identically to before. No regression in session lifecycle behaviour. | I8: Not Tested | J8: Functional | K8: Web | L8: AIO (Jira) | M8: EMI-5213 | N8: No | P8: B2B
A9: EMI-B2B-6721 | B9: 5.1.0 | C9: EMI-TC-4652 | D9: SessionTimeOutService is removed and no longer invoked | E9: High | F9: Refactor is complete. | G9: 1. Verify SessionTimeOutService does not exist in the codebase 2. Trigger session timeout scenario 3. Observe how timeout is handled | H9: SessionTimeOutService is absent. Timeout is handled entirely by SessionManager coroutine. No service binding or service lifecycle calls occur. | I9: Not Tested | J9: Functional | K9: Web | L9: AIO (Jira) | M9: EMI-5213 | N9: No | P9: B2B
A10: EMI-B2B-6722 | B10: 5.1.0 | C10: EMI-TC-4653 | D10: IdleTimerReceiver is removed and no broadcast intents are used for idle tracking | E10: High | F10: Refactor is complete. | G10: 1. Verify IdleTimerReceiver does not exist 2. Monitor system broadcast intents during app use 3. Trigger idle timeout | H10: IdleTimerReceiver is absent. No broadcast intents sent or received for idle timer. Idle tracking handled entirely within SessionManager. | I10: Not Tested | J10: Functional | K10: Web | L10: AIO (Jira) | M10: EMI-5213 | N10: No | P10: B2B
A11: EMI-B2B-6727 | B11: 5.1.0 | C11: EMI-TC-4658 | D11: SessionManager is provided as singleton in Koin modules | E11: High | F11: App is launched with updated Koin configuration. | G11: 1. Resolve SessionManager from Koin in MainActivity 2. Resolve SessionManager from Koin in another component 3. Compare instances | H11: Both resolutions return the same singleton instance. Koin module declares SessionManager with single() scope. | I11: Not Tested | J11: Functional | K11: Web | L11: AIO (Jira) | M11: EMI-5213 | N11: No | P11: B2B
A12: EMI-B2B-6728 | B12: 5.1.0 | C12: EMI-TC-4659 | D12: AppCoreModule caches environment settings — not re-read on every access | E12: High | F12: App is running. AppCoreModule is initialised. | G12: 1. Access environment settings multiple times via AppCoreModule 2. Monitor how often settings are read from source (file/prefs/network) | H12: Environment settings are read once and cached. Subsequent accesses return the cached value without re-reading the source. | I12: Not Tested | J12: Functional | K12: Web | L12: AIO (Jira) | M12: EMI-5213 | N12: No | P12: B2B
A13: EMI-B2B-6732 | B13: 5.1.0 | C13: EMI-TC-4663 | D13: Full session lifecycle: login, background app, foreground before timeout | E13: High | F13: User is logged in. | G13: 1. Log in 2. Background the app 3. Return to foreground before timeout elapses 4. Observe session state | H13: Session remains active on foreground return. Idle timer is handled correctly across background/foreground transitions. No unintended logout. | I13: Not Tested | J13: Functional | K13: Web | L13: AIO (Jira) | M13: EMI-5213 | N13: No | P13: B2B
A14: EMI-B2B-6751 | B14: 5.1.0 | C14: EMI-TC-5034 | D14: Unchecking the VAT checkbox removes VAT from the bill total | E14: High | F14: Edit bill form is open. VAT checkbox is currently checked. | G14: Uncheck the VAT checkbox. | H14: VAT is removed from the bill total. Total recalculates immediately. VAT line disappears from the bill summary. | I14: Not Tested | J14: Functional | K14: Web | L14: AIO (Jira) | N14: No | P14: B2B
A15: EMI-B2B-6752 | B15: 5.1.0 | C15: EMI-TC-5035 | D15: VAT checkbox state is saved correctly on form submission | E15: High | F15: Edit bill form is open. VAT checkbox toggled to a new state. | G15: Submit the edit bill form. | H15: Saved bill reflects the new VAT checkbox state. Re-opening the bill shows the checkbox in the saved position. Total matches the expected amount with or without VAT. | I15: Not Tested | J15: Functional | K15: Web | L15: AIO (Jira) | N15: No | P15: B2B
A16: EMI-B2B-6753 | B16: 5.1.0 | C16: EMI-TC-5036 | D16: Old VAT input or dropdown is no longer present in the edit form | E16: High | F16: Edit bill form is open after the update has been deployed. | G16: Inspect the form for any text input, number field, or dropdown previously used for VAT entry. | H16: No VAT text input or dropdown exists. Only the checkbox is present. No legacy VAT field remains in the DOM. | I16: Not Tested | J16: Functional | K16: Web | L16: AIO (Jira) | N16: No | P16: B2B
A17: EMI-B2B-6756 | B17: 5.1.0 | C17: EMI-TC-5039 | D17: Removing uneditable fields does not affect other editable fields | E17: High | F17: Edit bill form is open after removal of uneditable fields. | G17: Inspect and interact with the remaining editable fields (e.g. amount, description, VAT checkbox). | H17: All remaining editable fields are functional and properly laid out. No field shifts, overlaps, or broken spacing caused by the removal. | I17: Not Tested | J17: Functional | K17: Web | L17: AIO (Jira) | M17: EMI-5199 | N17: No | P17: B2B
A18: EMI-B2B-6763 | B18: 5.1.0 | C18: EMI-TC-5046 | D18: VAT checkbox state applies consistently across all line items in detailed view | E18: High | F18: Detailed bill with multiple line items is in edit mode. VAT checkbox is at the bill level. | G18: Toggle the VAT checkbox and inspect all line-item totals. | H18: VAT is applied or removed consistently across all line items. No line item retains a conflicting VAT state. Grand total recalculates correctly. | I18: Not Tested | J18: Functional | K18: Web | L18: AIO (Jira) | M18: EMI-5199 | N18: No | P18: B2B
A19: EMI-B2B-6730 | B19: 5.1.0 | C19: EMI-TC-4661 | D19: Unused constants are removed — no dead code references in modules | E19: Medium | F19: Refactor is complete. | G19: 1. Review Koin modules and AppCoreModule for any unused constants 2. Run static analysis / lint | H19: No unused constants in the updated modules. Lint passes without unused symbol warnings for removed items. | I19: Not Tested | J19: Functional | K19: Web | L19: AIO (Jira) | M19: EMI-5213 | N19: No | P19: B2B
A20: EMI-B2B-6759 | B20: 5.1.0 | C20: EMI-TC-5042 | D20: Single bill edit saves correctly with the new form structure | E20: Critical | F20: Single bill edit form open. User modifies amount and toggles VAT checkbox. | G20: Submit the form. | H20: Bill is saved successfully. Updated amount and VAT state are reflected when the bill is reopened. No error from missing removed fields. | I20: Not Tested | J20: Negative | K20: Web | L20: AIO (Jira) | M20: EMI-5199 | N20: No | P20: B2B
A21: EMI-B2B-6762 | B21: 5.1.0 | C21: EMI-TC-5045 | D21: Detailed bill edit saves correctly with the new form structure | E21: Critical | F21: Detailed bill edit form open. User modifies a line-item amount and checks the VAT checkbox. | G21: Submit the form. | H21: Bill is saved successfully. All changes persist on re-open. No error from missing removed fields. Line-item totals reflect the VAT state. | I21: Not Tested | J21: Negative | K21: Web | L21: AIO (Jira) | M21: EMI-5199 | N21: No | P21: B2B
A22: EMI-B2B-6713 | B22: 5.1.0 | C22: EMI-TC-4644 | D22: Reset flag mechanism prevents unnecessary coroutine restarts | E22: High | F22: User is actively using the app. Multiple rapid interactions occur. | G22: 1. Rapidly trigger multiple user interaction events 2. Observe coroutine job count and reset flag state | H22: Reset flag is set on first interaction and coroutine is restarted only once per idle cycle. No coroutine churn — multiple rapid events do not spawn multiple coroutine jobs. | I22: Not Tested | J22: Negative | K22: Web | L22: AIO (Jira) | M22: EMI-5213 | N22: No | P22: B2B
A23: EMI-B2B-6719 | B23: 5.1.0 | C23: EMI-TC-4650 | D23: BaseActivity is fully removed — no residual references exist | E23: High | F23: Refactor is complete. | G23: 1. Search codebase for any references to BaseActivity 2. Verify no classes extend BaseActivity | H23: BaseActivity does not exist. No classes extend or reference BaseActivity. Build succeeds without errors. | I23: Not Tested | J23: Negative | K23: Web | L23: AIO (Jira) | M23: EMI-5213 | N23: No | P23: B2B
A24: EMI-B2B-6735 | B24: 5.1.0 | C24: EMI-TC-4666 | D24: Multiple rapid session resets do not cause coroutine job accumulation | E24: High | F24: User is logged in. Rapid interactions occur. | G24: 1. Rapidly trigger 50+ user interaction events within a second 2. Monitor active coroutine job count | H24: Coroutine job count remains at 1 (the active timeout job). No job accumulation occurs. Reset flag mechanism prevents redundant restarts. | I24: Not Tested | J24: Negative | K24: Web | L24: AIO (Jira) | M24: EMI-5213 | N24: No | P24: B2B
A25: EMI-B2B-6729 | B25: 5.1.0 | C25: EMI-TC-4660 | D25: AppCoreModule cache is invalidated correctly when environment changes | E25: Medium | F25: App is running. Cached environment settings exist. | G25: 1. Change the environment configuration 2. Access environment settings via AppCoreModule | H25: Cache is refreshed after environment change. Stale cached values are not returned after a config update. | I25: Not Tested | J25: Negative | K25: Web | L25: AIO (Jira) | M25: EMI-5213 | N25: No | P25: B2B
A26: EMI-B2B-6754 | B26: 5.1.0 | C26: EMI-TC-5037 | D26: Select Beneficiary field is removed from the edit bill form | E26: Critical | F26: Edit bill form is open. | G26: Inspect the edit bill form for the Select Beneficiary field. | H26: The Select Beneficiary field is not present in the form. It is not disabled or read-only — it is completely absent. No empty placeholder remains. | I26: Not Tested | J26: Edge / Boundary | K26: Web | L26: AIO (Jira) | N26: No | P26: B2B
A27: EMI-B2B-6757 | B27: 5.1.0 | C27: EMI-TC-5040 | D27: Disabled fields are not sent in the form payload when submitting | E27: High | F27: Edit bill form submitted after removal of uneditable fields. | G27: Submit the form and inspect the API request payload. | H27: The payload does not include Select Beneficiary or Issue Date fields. No null or empty values for removed fields are sent to the backend. | I27: Not Tested | J27: Edge / Boundary | K27: Web | L27: AIO (Jira) | M27: EMI-5199 | N27: No | P27: B2B
A28: EMI-B2B-6736 | B28: 5.1.0 | C28: EMI-TC-4856 | D28: Annotated method executes when user holds the required privilege | E28: Critical | F28: Repository method annotated @RequiresPrivilege(ADMIN). User session carries ADMIN privilege. | G28: Call the annotated repository method. | H28: Method executes successfully. Guard intercepts, confirms privilege, and delegates to the real implementation. | I28: Not Tested | J28: Security | K28: Web | L28: AIO (Jira) | N28: No | P28: B2B
A29: EMI-B2B-6739 | B29: 5.1.0 | C29: EMI-TC-4859 | D29: Guard blocks call and throws when required privilege is missing | E29: Critical | F29: Repository method requires WRITE. Current user has READ only. | G29: Call the WRITE-guarded method as a READ-only user. | H29: Guard throws an access-denied exception before the real method body is entered. No data is read or written. | I29: Not Tested | J29: Security | K29: Web | L29: AIO (Jira) | M29: EMI-5208 | N29: No | P29: B2B
A30: EMI-B2B-6740 | B30: 5.1.0 | C30: EMI-TC-4860 | D30: Guard delegates call with original arguments when privilege passes | E30: Critical | F30: Repository method requires READ. User has READ. Method expects arguments (userId=42). | G30: Call the guarded method with userId=42. | H30: Real method is invoked with userId=42 unchanged. Return value is passed back to the caller unmodified. | I30: Not Tested | J30: Security | K30: Web | L30: AIO (Jira) | M30: EMI-5208 | N30: No | P30: B2B
A31: EMI-B2B-6741 | B31: 5.1.0 | C31: EMI-TC-4861 | D31: Privilege is evaluated at call time, not at proxy creation time | E31: Critical | F31: Proxy created while user has ADMIN. User privilege is downgraded to READ before the call. | G31: Call an ADMIN-required method after the privilege downgrade. | H31: Guard uses the current session context and throws access-denied. Construction-time privilege is not cached or reused. | I31: Not Tested | J31: Security | K31: Web | L31: AIO (Jira) | M31: EMI-5208 | N31: No | P31: B2B
A32: EMI-B2B-6744 | B32: 5.1.0 | C32: EMI-TC-4864 | D32: guardedSingleOf registers a singleton guarded proxy in Koin | E32: Critical | F32: Koin module uses guardedSingleOf(::UserRepositoryImpl) bind UserRepository::class. | G32: Resolve UserRepository from Koin twice. | H32: Both resolutions return the same instance. The resolved object is a PrivilegeGuard proxy, not the raw implementation. | I32: Not Tested | J32: Security | K32: Web | L32: AIO (Jira) | M32: EMI-5208 | N32: No | P32: B2B
A33: EMI-B2B-6714 | B33: 5.1.0 | C33: EMI-TC-4645 | D33: SessionManager cancels coroutine cleanly on user logout | E33: High | F33: User is logged in. Session timeout coroutine is active. | G33: 1. User manually logs out 2. Inspect coroutine state | H33: Session timeout coroutine is cancelled on logout. No timeout fires after logout. No memory leaks or dangling coroutine jobs. | I33: Not Tested | J33: Security | K33: Web | L33: AIO (Jira) | M33: EMI-5213 | N33: No | P33: B2B
A34: EMI-B2B-6715 | B34: 5.1.0 | C34: EMI-TC-4646 | D34: SessionManager handles token refresh before expiry | E34: High | F34: User is logged in. Access token is nearing expiry. | G34: 1. Allow token to approach expiry threshold 2. Observe SessionManager behaviour | H34: SessionManager initiates token refresh before expiry. User session continues uninterrupted. New token is stored and used for subsequent requests. | I34: Not Tested | J34: Security | K34: Web | L34: AIO (Jira) | M34: EMI-5213 | N34: No | P34: B2B
A35: EMI-B2B-6716 | B35: 5.1.0 | C35: EMI-TC-4647 | D35: SessionManager logs out user when token refresh fails | E35: High | F35: User is logged in. Access token is expired. Refresh attempt fails (e.g., network error or revoked token). | G35: 1. Allow token to expire 2. Simulate refresh failure 3. Observe app behaviour | H35: SessionManager detects refresh failure. User is redirected to login screen. Session is fully cleared. | I35: Not Tested | J35: Security | K35: Web | L35: AIO (Jira) | M35: EMI-5213 | N35: No | P35: B2B
A36: EMI-B2B-6717 | B36: 5.1.0 | C36: EMI-TC-4648 | D36: Token lifecycle is managed in MainActivity, not BaseActivity | E36: High | F36: Code review / instrumentation confirms BaseActivity has been removed. | G36: 1. Verify BaseActivity no longer exists in the codebase 2. Verify token handling logic is present in MainActivity 3. Run a session scenario end-to-end | H36: No BaseActivity class exists. Token refresh and session expiry handling operate correctly from MainActivity. No regressions in token behaviour. | I36: Not Tested | J36: Security | K36: Web | L36: AIO (Jira) | M36: EMI-5213 | N36: No | P36: B2B
A37: EMI-B2B-6718 | B37: 5.1.0 | C37: EMI-TC-4649 | D37: Token expiry during background state triggers correct session handling on resume | E37: High | F37: User puts app in background. Token expires while app is backgrounded. | G37: 1. Log in and background the app 2. Wait for token to expire 3. Bring app to foreground | H37: On resume, SessionManager detects expired token. User is redirected to login screen. No crash or undefined behaviour on resume. | I37: Not Tested | J37: Security | K37: Web | L37: AIO (Jira) | M37: EMI-5213 | N37: No | P37: B2B
A38: EMI-B2B-6737 | B38: 5.1.0 | C38: EMI-TC-4857 | D38: Unannotated method bypasses the guard with no privilege check | E38: High | F38: Same repository has a second method with no annotation. User has no privileges. | G38: Call the unannotated method. | H38: Method executes normally. No privilege check is performed and no exception is thrown. | I38: Not Tested | J38: Security | K38: Web | L38: AIO (Jira) | N38: No | P38: B2B
A39: EMI-B2B-6738 | B39: 5.1.0 | C39: EMI-TC-4858 | D39: Invalid privilege value on annotation fails at startup | E39: High | F39: A repository method is annotated with an undefined privilege constant. | G39: Start the application with @RequiresPrivilege(UNDEFINED) on a repository method. | H39: Application throws a configuration exception naming the invalid privilege. It does not start silently. | I39: Not Tested | J39: Security | K39: Web | L39: AIO (Jira) | N39: No | P39: B2B
A40: EMI-B2B-6743 | B40: 5.1.0 | C40: EMI-TC-4863 | D40: Guard correctly intercepts Kotlin suspend functions | E40: High | F40: Repository has a suspend fun annotated with @RequiresPrivilege. User lacks the privilege. | G40: Call the suspend function from a coroutine scope without the required privilege. | H40: Guard throws access-denied within the coroutine. Exception propagates to the coroutine's exception handler without context corruption. | I40: Not Tested | J40: Security | K40: Web | L40: AIO (Jira) | M40: EMI-5208 | N40: No | P40: B2B
...

Sheet Deep Payment
A1: TC ID | B1: Sub-Area | C1: Source ID | D1: Title | E1: Priority | F1: Preconditions | G1: Steps | H1: Expected Result | I1: Status | J1: Test Type | K1: Interface | L1: Source | M1: Jira Ref | N1: Automated | O1: Automated By | P1: Channel
A2: EMI-B2B-1043 | B2: Deep Payment | C2: EMI-TC-6637 | D2: Guest payment with OTP success | E2: Critical | F2: OTP required by risk rule for guest | G2: 1. Start guest payment. 2. Provide valid payer info. 3. Trigger OTP. 4. Enter correct OTP within allowed time. | H2: OTP is verified; otp_verified=true recorded. User continues to gateway. Flow same as D1 on success. | I2: Not Tested | J2: Functional | K2: Web | L2: AIO (Jira) | M2: EMI-5368 | N2: No | P2: B2B
A3: EMI-B2B-1052 | B3: Deep Payment | C3: EMI-TC-6646 | D3: Session expiry during payment | E3: Critical | F3: Logged-in user session times out mid-flow | G3: 1. Start wallet payment. 2. Let session expire before confirm. 3. Try to confirm payment. | H3: User is forced to re-authenticate. Payment not executed without valid session. No inconsistent attempts created. After login, user can retry. | I3: Not Tested | J3: Functional | K3: Web | L3: AIO (Jira) | M3: EMI-5368 | N3: No | P3: B2B
A4: EMI-B2B-1074 | B4: Deep Payment | C4: EMI-TC-6668 | D4: OTP requirement is skipped when risk config does not require it | E4: Critical | F4: A payable invoice/bill with an ACTIVE payment link exists. OTP is NOT required by the current risk configuration. | G4: 1. Open hosted payment page as a guest. 2. Enter valid payer info. 3. Observe whether OTP is requested. | H4: OTP step is not presented to the payer. Payment proceeds directly to gateway without OTP. No OTP record is created. payment_attempt.otp_verified reflects false/null per defined behavior. Flow is consistent with risk config setting. | I4: Not Tested | J4: Functional | K4: Web | L4: AIO (Jira) | M4: EMI-5368 | N4: No | P4: B2B
A5: EMI-B2B-1075 | B5: Deep Payment | C5: EMI-TC-6669 | D5: Partial payment via wallet — invoice remains open, link stays ACTIVE | E5: Critical | F5: An invoice/bill supports partial payment (per invoice/bill rules). A payment link exists. Logged-in payer pays less than the full outstanding amount. | G5: 1. Open hosted payment page as a logged-in user. 2. Choose 'Pay with Wallet'. 3. Submit a partial amount (less than full outstanding). 4. Verify payment is accepted. 5. Check invoice outstanding balance. 6. Check payment link status. | H5: Payment attempt is marked SUCCESS for the partial amount. Invoice outstanding balance is reduced by the paid amount (not closed). Invoice remains in partially-paid / open state per invoice/bill rules. payment_link status remains ACTIVE (not CONSUMED). Another payment can be initiated through the same link. | I5: Not Tested | J5: Functional | K5: Web | L5: AIO (Jira) | M5: EMI-5368 | N5: No | P5: B2B
A6: EMI-B2B-1107 | B6: Deep Payment | C6: EMI-TC-6874 | D6: Regenerate QR explicitly (if API supports regenerate) | E6: Critical | F6: Payment link is ACTIVE | G6: 1. Call QR regenerate endpoint/flag. 2. Decode new QR content. 3. Compare with old QR. | H6: Depending on design: either 1) New QR resource but still resolves to same payment session, or 2) Regeneration disabled and existing QR is returned with clear message. No inconsistent states. | I6: Not Tested | J6: Functional | K6: API | L6: AIO (Jira) | M6: EMI-5428 | N6: No | P6: B2B
A7: EMI-B2B-1120 | B7: Deep Payment | C7: EMI-TC-6887 | D7: Correct commission & VAT calculation for wallet payment | E7: Critical | F7: 1. Commission & VAT configuration for payment-link wallet transactions is defined. 2. Valid wallet payment link exists. | G7: 1. Initiate wallet payment via payment link for a known amount. | H7: 1. System calculates commission according to configuration. 2. System calculates VAT on commission/amount as defined. 3. Net amount credited/debited is correct. 4. Ledger entries reflect commission and VAT amounts correctly. | I7: Not Tested | J7: Functional | K7: Web | L7: AIO (Jira) | M7: EMI-5442 | N7: No | P7: B2B
A8: EMI-B2B-1121 | B8: Deep Payment | C8: EMI-TC-6888 | D8: Correct commission & VAT calculation for guest payment | E8: Critical | F8: 1. Commission & VAT configuration for payment-link guest/gateway transactions is defined. | G8: 1. Initiate guest payment via payment link for a known amount. | H8: 1. Commission and VAT values are calculated per configuration. 2. Business/net settlement amounts are correct. 3. Ledger entries reflect correct breakdown (principal, commission, VAT). | I8: Not Tested | J8: Functional | K8: Web | L8: AIO (Jira) | M8: EMI-5442 | N8: No | P8: B2B
A9: EMI-B2B-1129 | B9: Deep Payment | C9: EMI-TC-6896 | D9: Ledger entries for wallet payment – bank/reserve split | E9: Critical | F9: 1. Configuration exists for bank/reserve split for wallet transactions via payment link. 2. Valid wallet payment link. | G9: 1. Perform a successful wallet payment via link. | H9: 1. Ledger entries created for customer wallet debit, business/beneficiary credit. 2. Bank/reserve split entries are created as per rules. 3. All amounts balance correctly (accounting equation holds). | I9: Not Tested | J9: Functional | K9: Web | L9: AIO (Jira) | M9: EMI-5442 | N9: No | P9: B2B
A10: EMI-B2B-1130 | B10: Deep Payment | C10: EMI-TC-6897 | D10: Ledger entries for guest payment – bank/reserve split | E10: Critical | F10: 1. Configuration exists for bank/reserve split for gateway transactions. | G10: 1. Perform a successful guest payment via link. | H10: 1. Ledger entries reflect gateway/bank accounts and reserve postings correctly. 2. Commission and VAT are posted to correct GL accounts. 3. Entries fully balanced. | I10: Not Tested | J10: Functional | K10: Web | L10: AIO (Jira) | M10: EMI-5442 | N10: No | P10: B2B
A11: EMI-B2B-1187 | B11: Deep Payment | C11: EMI-TC-7033 | D11: Download action saves QR/link artifact successfully | E11: Critical | F11: Successful link generation; storage/photos permission allowed (if required) | G11: 1. Tap Download. 2. Approve permission prompts (if shown). | H11: File/image is saved successfully (Photos/Files per implementation). User gets a success confirmation (toast/snackbar) if designed. | I11: Not Tested | J11: Functional | K11: Web | L11: AIO (Jira) | M11: EMI-5461 | N11: No | P11: B2B
A12: EMI-B2B-1221 | B12: Deep Payment | C12: EMI-TC-7067 | D12: OTP – Successful Verification | E12: Critical | F12: On OTP screen; valid OTP delivered | G12: 1. Enter correct OTP 2. Submit | H12: OTP verified; user moves to Payment step and payment is triggered | I12: Not Tested | J12: Functional | K12: Web | L12: AIO (Jira) | M12: EMI-5463 | N12: No | P12: B2B
A13: EMI-B2B-1232 | B13: Deep Payment | C13: EMI-TC-7078 | D13: Full Navigation – Wallet | E13: Critical | F13: Valid wallet link | G13: 1. Link Entry → Summary → Payer Info (with amount) → [OTP] → Payment → Result | H13: Same as TC-32 but including amount field; all transitions correct and data preserved | I13: Not Tested | J13: Functional | K13: Web | L13: AIO (Jira) | M13: EMI-5463 | N13: No | P13: B2B
... A158: EMI-B2B-1111 | B158: Deep Payment | C158: EMI-TC-6878 | D158: Generate QR for invalid status link (EXPIRED/CANCELLED) | E158: High | F158: Payment link exists but not ACTIVE | G158: 1. Call QR generate for EXPIRED/CANCELLED link ID. | H158: API rejects with 4xx error indicating invalid link status; no QR created. | I158: Not Tested | J158: Negative | K158: Web | L158: AIO (Jira) | M158: EMI-5428 | N158: No | P158: B2B
A159: EMI-B2B-1112 | B159: Deep Payment | C159: EMI-TC-6879 | D159: Malformed request payload | E159: High | G159: 1. Call QR generate with missing mandatory fields / invalid JSON. | H159: API returns 400 Bad Request with validation errors; no QR generated. | I159: Not Tested | J159: Negative | K159: API | L159: AIO (Jira) | M159: EMI-5428 | N159: No | P159: B2B
A160: EMI-B2B-1132 | B160: Deep Payment | C160: EMI-TC-6899 | D160: Invoice/bill remains unchanged on payment failure | E160: High | F160: 1. Invoice/bill is “Pending/Unpaid”. | G160: 1. Attempt payment via link that fails (e.g. gateway decline). | H160: 1. Invoice/bill status remains “Pending/Unpaid”. 2. No partial updates to invoice financial fields occur. | I160: Not Tested | J160: Negative | K160: Web | L160: AIO (Jira) | M160: EMI-5442 | N160: No | P160: B2B
A161: EMI-B2B-1165 | B161: Deep Payment | C161: EMI-TC-7011 | D161: Error state – network error | E161: High | F161: Simulate network failure (e.g., offline mode) | G161: 1. Turn off network. 2. Open Payment Link Management screen or pull-to-refresh. | H161: Error state UI appears with proper message and retry option; no crash. | I161: Not Tested | J161: Negative | K161: Web | L161: AIO (Jira) | M161: EMI-5460 | N161: No | P161: B2B
A162: EMI-B2B-1166 | B162: Deep Payment | C162: EMI-TC-7012 | D162: Error state – API error (server 5xx) | E162: High | F162: Simulate server error from backend | G162: 1. Open screen while backend returns error. | H162: Error message is displayed; user can retry; previous data not incorrectly shown as updated. | I162: Not Tested | J162: Negative | K162: Web | L162: AIO (Jira) | M162: EMI-5460 | N162: No | P162: B2B
A163: EMI-B2B-1167 | B163: Deep Payment | C163: EMI-TC-7013 | D163: Retry from error state | E163: High | F163: User currently sees error state | G163: 1. On error state, tap “Retry”. 2. Ensure backend is healthy. | H163: System retries fetch; when successful, normal list is displayed. | I163: Not Tested | J163: Negative | K163: Web | L163: AIO (Jira) | M163: EMI-5460 | N163: No | P163: B2B
A164: EMI-B2B-1176 | B164: Deep Payment | C164: EMI-TC-7022 | D164: Payment Links module loads without crash | E164: High | F164: Business app installed; user logged in | G164: 1. Open Business app. 2. Navigate to Bills area and open any bill details (where feature is exposed). | H164: App does not crash. Payment Links feature area loads normally (no missing module/dependency errors). | I164: Not Tested | J164: Negative | K164: Web | L164: AIO (Jira) | M164: EMI-5461 | N164: No | P164: B2B
A165: EMI-B2B-1183 | B165: Deep Payment | C165: EMI-TC-7029 | D165: QR code is rendered successfully | E165: High | F165: Successful link generation | G165: 1. Open link creation screen. | H165: QR code is displayed (not blank/placeholder/error). | I165: Not Tested | J165: Negative | K165: Web | L165: AIO (Jira) | M165: EMI-5461 | N165: No | P165: B2B
A166: EMI-B2B-1193 | B166: Deep Payment | C166: EMI-TC-7039 | D166: Retry after generation failure works | E166: High | F166: Mock/backend can return failure then success | G166: 1. Configure failure response. 2. Tap Share Payment Link → observe error. 3. Configure success response. 4. Retry. | H166: On failure: user sees friendly error + can retry. On retry: link generation succeeds and screen opens. | I166: Not Tested | J166: Negative | K166: Web | L166: AIO (Jira) | M166: EMI-5461 | N166: No | P166: B2B
A167: EMI-B2B-1194 | B167: Deep Payment | C167: EMI-TC-7040 | D167: Offline/no network handling for generation | E167: High | F167: Device offline OR mock simulates no network | G167: 1. Disable network. 2. Tap Share Payment Link. | H167: Clear offline/network error shown. No crash; user can retry after reconnecting. | I167: Not Tested | J167: Negative | K167: Web | L167: AIO (Jira) | M167: EMI-5461 | N167: No | P167: B2B
A168: EMI-B2B-1195 | B168: Deep Payment | C168: EMI-TC-7041 | D168: Mock API support: all required endpoints used in flow | E168: High | F168: App configured to use mock environment | G168: 1. Run full flow (bill details → generate → copy/share/download). | H168: Flow completes using mock endpoints without missing/404 errors. | I168: Not Tested | J168: Negative | K168: Web | L168: AIO (Jira) | M168: EMI-5461 | N168: No | P168: B2B
A169: EMI-B2B-1196 | B169: Deep Payment | C169: EMI-TC-7042 | D169: Mock API error mapping: 4xx/5xx shows correct message | E169: High | F169: Mock returns 400/401/500 (as applicable) | G169: 1. Trigger link generation with each error response type. | H169: App shows appropriate error messaging and remains usable (no crash, no infinite loader). | I169: Not Tested | J169: Negative | K169: Web | L169: AIO (Jira) | M169: EMI-5461 | N169: No | P169: B2B
A170: EMI-B2B-1197 | B170: Deep Payment | C170: EMI-TC-7043 | D170: Bill “target types” coverage for link generation | E170: High | F170: Multiple bill target types exist per requirements | G170: 1. For each bill target type, open bill details. 2. Tap Share Payment Link. | H170: Link generation supported for each required target type (no unsupported/incorrect routing). | I170: Not Tested | J170: Negative | K170: Web | L170: AIO (Jira) | M170: EMI-5461 | N170: No | P170: B2B
A171: EMI-B2B-1212 | B171: Deep Payment | C171: EMI-TC-7058 | D171: Payer Info – Mobile Format | E171: High | F171: On Payer Info screen | G171: 1. Enter invalid mobile format (e.g., letters, too short/long) 2. Continue | H171: Field shows error; user cannot proceed until a valid mobile number is entered | I171: Not Tested | J171: Negative | K171: Web | L171: AIO (Jira) | M171: EMI-5463 | N171: No | P171: B2B
... A702: EMI-B2B-1718 | B702: Deep Payment | C702: EMI-TC-7663 | D702: Accessibility – VoiceOver labels | E702: Low | F702: VoiceOver enabled | G702: 1. Enable VoiceOver 2. Navigate to Payment Link Management screen 3. Focus on list items and controls | H702: All interactive elements (filters, list items, cancel button) have proper accessibility labels and hints; status, expiry, and access count are read meaningfully. | I702: Not Tested | J702: Usability | K702: Web | L702: AIO (Jira) | M702: EMI-5459 | N702: No | P702: B2B

Sheet PoS Transactions
A1: TC ID | B1: Sub-Area | C1: Source ID | D1: Title | E1: Priority | F1: Preconditions | G1: Steps | H1: Expected Result | I1: Status | J1: Test Type | K1: Interface | L1: Source | M1: Jira Ref | N1: Automated | O1: Automated By | P1: Channel
A2: EMI-B2B-3226 | B2: ACH & VIBAN per TID | C2: TC-ACH-01 | D2: Matched Aggregate – ACH Item Generation | E2: Critical | F2: Aggregate is matched and funded by Reconciliation; merchant is eligible | G2: 1. Handoff matched aggregate to settlement. 2. Build settlement batch. 3. Inspect generated ACH item. | H2: One settlement item is created per TID group. item_ref, batch_ref, TID, wallet, VIBAN and aggregate net amount are persisted. Item is AWAITING_APPROVAL. | I2: NA | J2: Functional | K2: Web | L2: New (this audit) | N2: No | P2: B2B
A3: EMI-B2B-3229 | B3: ACH & VIBAN per TID | C3: TC-ACH-04 | D3: Gate 2 – Business Eligibility and Sanctions Check | E3: Critical | F3: Aggregate matched; merchant status changes after initial screening | G3: 1. Change business eligibility before batch release. 2. Run Gate 2. 3. Repeat with a newly matched sanctions hit. | H3: Failed eligibility or sanctions screening excludes the item from release. Funds remain in the omnibus. No ACH instruction is released. | I3: NA | J3: Functional | K3: Web | L3: New (this audit) | N3: No | P3: B2B
A4: EMI-B2B-3230 | B4: ACH & VIBAN per TID | C4: TC-ACH-05 | D4: ACH Reference Propagation | E4: Critical | F4: Valid settlement item with known batch_ref | G4: 1. Generate ACH instruction. 2. Inspect ACH request. | H4: batch_ref is written to the ACH notes/remittance field unchanged. The same reference is available for subsequent clearing. | I4: NA | J4: Functional | K4: Web | L4: New (this audit) | N4: No | P4: B2B
A5: EMI-B2B-3231 | B5: ACH & VIBAN per TID | C5: TC-ACH-06 | D5: Maker-Checker Approval | E5: Critical | F5: Default automatic mode is disabled | G5: 1. Generate valid ACH items. 2. Review approval status. 3. Finance approves. 4. Release transfer. | H5: ACH item cannot be released before Finance approval. Approval and release are audit logged with actor and batch_ref. | I5: NA | J5: Functional | K5: Web | L5: New (this audit) | N5: No | P5: B2B
A6: EMI-B2B-3233 | B6: ACH & VIBAN per TID | C6: TC-ACH-08 | D6: Intraday Credit Clears Pending Cash-In | E6: Critical | F6: ACH executed; intraday statement contains credit with matching batch_ref; credit amount equals pending amount | G6: 1. Process intraday statement. 2. Find credit using batch_ref. 3. Check pending cash-in. | H6: Existing aggregated CASH IN changes from PENDING → SUCCESSFUL. Member per-TID entries settle accordingly. No new cash-in is created. | I6: NA | J6: Functional | K6: Web | L6: New (this audit) | N6: No | P6: B2B
A7: EMI-B2B-3234 | B7: ACH & VIBAN per TID | C7: TC-ACH-09 | D7: Intraday Credit Amount Mismatch | E7: Critical | F7: Credit reference matches batch_ref, but credited amount differs from pending amount | G7: 1. Process intraday statement. 2. Match reference. 3. Compare amounts. | H7: Pending cash-in remains unchanged/PENDING. Nothing is partially cleared. Item moves to discrepancy queue. No additional cash-in is booked. | I7: NA | J7: Functional | K7: Web | L7: New (this audit) | N7: No | P7: B2B
A8: EMI-B2B-3235 | B8: ACH & VIBAN per TID | C8: TC-ACH-10 | D8: Credit Without Valid Reference | E8: Critical | F8: Intraday credit has no recognizable batch_ref or contains a malformed/truncated reference | G8: 1. Process statement credit. 2. Run clearing job. | H8: Credit is parked for Ops. No matching by amount/date is attempted. No pending cash-in is cleared. Reference integrity issue is raised. | I8: NA | J8: Functional | K8: Web | L8: New (this audit) | N8: No | P8: B2B
A9: EMI-B2B-3238 | B9: ACH & VIBAN per TID | C9: TC-ACH-13 | D9: Transfer Returned After Successful Clearing | E9: Critical | F9: Pending cash-in was cleared successfully; bank subsequently returns the transfer | G9: 1. Process return notification. 2. Reverse the cleared cash-in. | H9: An explicit compensating reversal entry is created. Original entry is not deleted or amended. Reversal carries the same batch_ref. | I9: NA | J9: Functional | K9: Web | L9: New (this audit) | N9: No | P9: B2B
A10: EMI-B2B-3242 | B10: ACH & VIBAN per TID | C10: TC-ACH-17 | D10: Unmatched or Held Aggregate Excluded | E10: Critical | F10: Aggregate exists but is unmatched, unfunded, or in COMPLIANCE_HOLD (Gate 1) | G10: 1. Attempt to build settlement batch. 2. Inspect generated ACH items. | H10: No ACH instruction is generated at all for the unmatched/held aggregate. Funds are not moved. | I10: NA | J10: Functional | K10: Web | L10: New (this audit) | N10: No | P10: B2B
A11: EMI-B2B-3303 | B11: ACH & VIBAN per TID | C11: TC-ACH-78 | D11: Valid Payment ID and exact amount clears the matching pending aggregate | E11: Critical | F11: A pending POS settlement aggregate exists with a valid Payment id and known expected amount. An inbound bank statement credit is available. | G11: 1. Process the inbound statement. 2. Provide the matching Payment id. 3. Verify the credited amount equals the pending aggregate amount. 4. Run the intraday settlement job. | H11: The correct pending aggregate is identified and cleared. Settlement is completed against the existing aggregate. | I11: Not Tested | J11: Functional | K11: Web | L11: New (this audit) | N11: No | P11: B2B
A12: EMI-B2B-3304 | B12: ACH & VIBAN per TID | C12: TC-ACH-79 | D12: Intraday credit does not create a new CASH IN | E12: Critical | F12: A pending POS aggregate exists and its corresponding bank credit is available. | G12: 1. Record the ledger state before processing. 2. Process the inbound statement through the intraday job. 3. Review the ledger after processing. | H12: The existing pending aggregate is cleared. No additional/new CASH IN transaction is created for the same settlement. | I12: Not Tested | J12: Functional | K12: Web | L12: New (this audit) | N12: No | P12: B2B
A13: EMI-B2B-3305 | B13: ACH & VIBAN per TID | C13: TC-ACH-80 | D13: Successful aggregate settlement settles all member POS transactions | E13: Critical | F13: A settlement aggregate contains multiple POS member transactions. Matching bank credit is available. | G13: 1. Process the matching bank credit. 2. Run intraday settlement. 3. Review the aggregate and all member transactions. | H13: The aggregate is settled and all eligible member POS transactions are moved to the appropriate settled state. | I13: Not Tested | J13: Functional | K13: Web | L13: New (this audit) | N13: No | P13: B2B
... A180: EMI-B2B-3404 | B180: Non-Functional | C180: PT-NFR-01 | D180: Callback ingestion sustains terminal peak load | E180: Critical | F180: Peak terminal callback volume | G180: 1. Drive sustained callback load and measure ingestion latency and error rate | H180: Every callback is ingested exactly once within the agreed latency; none is dropped under load | I180: Not Tested | J180: Performance / NFR | K180: Web | L180: New (this audit) | N180: No | P180: B2B
A181: EMI-B2B-3466 | B181: POS | C181: EMI-TC-8481 | D181: Admin KPI cards | E181: High | G181: 1. Open PoS Orders | H181: Cards shown: Open orders, Awaiting export, With provider, Active | I181: Not Tested | J181: Functional | K181: Web | L181: AIO (Jira) | M181: EMI-5786 | N181: No | P181: B2B
A182: EMI-B2B-3475 | B182: POS | C182: EMI-TC-8490 | D182: Full provisioning lifecycle transitions | E182: High | G182: 1. Walk an order through: Validating → Approved → Sent to Provider → Shipping → Activating → Active | H182: Each transition succeeds; timeline logged | I182: Not Tested | J182: Functional | K182: Web | L182: AIO (Jira) | M182: EMI-5786 | N182: No | P182: B2B
A183: EMI-B2B-3478 | B183: POS | C183: EMI-TC-8493 | D183: Mark as Sent to Provider (bulk) | E183: High | G183: 1. After export, select exported orders 2. Click Mark as Sent to Provider | H183: Status updates for all selected orders | I183: Not Tested | J183: Functional | K183: Web | L183: AIO (Jira) | M183: EMI-5786 | N183: No | P183: B2B
A184: EMI-B2B-3486 | B184: POS | C184: EMI-TC-8501 | D184: Cancellation before Sent to Provider | E184: High | G184: 1. Cancel an Approved order | H184: Order cancelled successfully | I184: Not Tested | J184: Functional | K184: Web | L184: AIO (Jira) | M184: EMI-5786 | N184: No | P184: B2B
A185: EMI-B2B-3487 | B185: POS | C185: EMI-TC-8502 | D185: Cancellation after Sent to Provider blocked | E185: High | G185: 1. Attempt to cancel a Sent to Provider order | H185: Cancellation is blocked | I185: Not Tested | J185: Functional | K185: Web | L185: AIO (Jira) | M185: EMI-5786 | N185: No | P185: B2B
A186: EMI-B2B-3494 | B186: POS | C186: EMI-TC-8514 | D186: Workflow: full provisioning lifecycle | E186: High | G186: 1. Transition order through all states | H186: Each transition succeeds: Requesting → Validating → Approved → Sent to Provider → Shipping → Activating → Active | I186: Not Tested | J186: Functional | K186: Web | L186: AIO (Jira) | M186: EMI-5788 | N186: No | P186: B2B
A187: EMI-B2B-3405 | B187: POS | C187: EMI-TC-8420 | D187: POS product analysis report generates | E187: Medium | G187: 1. Trigger POS product analysis via admin | H187: Analysis report is generated with relevant PoS metrics | I187: Not Tested | J187: Functional | K187: Web | L187: AIO (Jira) | M187: EMI-5746 | N187: No | P187: B2B
A188: EMI-B2B-3406 | B188: POS | C188: EMI-TC-8421 | D188: Data accuracy validation | E188: Medium | G188: 1. Compare analysis output with raw PoS data | H188: All values match source data | I188: Not Tested | J188: Functional | K188: Web | L188: AIO (Jira) | M188: EMI-5746 | N188: No | P188: B2B
A189: EMI-B2B-3408 | B189: POS | C189: EMI-TC-8423 | D189: Bill Items rename | E189: Medium | G189: 1. Open More menu on iOS | H189: Old "Products" entry now reads "Bill Items" | I189: Not Tested | J189: Functional | K189: Web | L189: AIO (Jira) | M189: EMI-5782 | N189: No | P189: B2B
A190: EMI-B2B-3409 | B190: POS | C190: EMI-TC-8424 | D190: New Products section with tabs | E190: Medium | G190: 1. Tap Products in More menu | H190: Two tabs appear: "My Products" and "All Products" | I190: Not Tested | J190: Functional | K190: Web | L190: AIO (Jira) | M190: EMI-5782 | N190: No | P190: B2B
A191: EMI-B2B-3411 | B191: POS | C191: EMI-TC-8426 | D191: Manage CTA for active subscription | E191: Medium | G191: 1. Open All Products as user with active PoS | H191: CTA reads "Manage" instead of "Configure & Request" | I191: Not Tested | J191: Functional | K191: Web | L191: AIO (Jira) | M191: EMI-5782 | N191: No | P191: B2B
A192: EMI-B2B-3412 | B192: POS | C192: EMI-TC-8427 | D192: Order in Progress badge | E192: Medium | G192: 1. Open All Products with a pending PoS order | H192: "Order in Progress" badge shown on PoS card | I192: Not Tested | J192: Functional | K192: Web | L192: AIO (Jira) | M192: EMI-5782 | N192: No | P192: B2B
... A296: EMI-B2B-3516 | B296: POS | C296: EMI-TC-8629 | D296: Payer info removed (bill payment) - Android | E296: Low | G296: 1. Open Payment Link for bill payment on Android | H296: No payer info screen | I296: Not Tested | J296: Usability | K296: Web | L296: AIO (Jira) | M296: EMI-5791 | N296: No | P296: B2B
A297: EMI-B2B-3523 | B297: PoS Commission Config | C297: TC-Commission-03 | D297: PoS Settlement Cash-In Is Distinguished From a Wallet Top-Up | E297: High | F297: A PoS settlement cash-in and an ordinary wallet top-up, both standard CASH IN | G297: 1. Price both 2. Compare the schemes resolved and the fees charged | H297: The PoS settlement cash-in is priced by the PoS scheme and the top-up by its own; the Platform value is what separates them; a PoS settlement is never priced as a generic top-up | I297: Not Tested | J297: Functional | K297: Web | L297: New (this audit) | N297: No | P297: B2B
A298: EMI-B2B-3524 | B298: PoS Commission Config | C298: TC-Commission-04 | D298: The Priced Object Is the Aggregated Cash-In per Settlement Batch | E298: High | F298: A settlement batch created in EMI-5989 with Platform = PoS | G298: 1. Inspect the object passed to the commission engine at pricing time | H298: The priced object is the aggregated cash-in for the batch, carrying Platform = PoS; no individual card transaction is passed to the engine | I298: Not Tested | J298: Functional | K298: Web | L298: New (this audit) | N298: No | P298: B2B
A299: EMI-B2B-3526 | B299: PoS Commission Config | C299: TC-Commission-06 | D299: Commission Base Is the Net That Arrived, Not Gross | E299: High | F299: A settlement batch whose Net Settlement Amount is already net of ANB interchange, scheme fee and ANB VAT | G299: 1. Price the batch 2. Compare the commission base with the Net Settlement Amount and with the gross | H299: The base is the net amount that arrived; ANB's interchange, scheme fee, VAT and other charges are never recalculated, never added back and never priced on gross | I299: Not Tested | J299: Functional | K299: Web | L299: New (this audit) | N299: No | P299: B2B
